Workbook

Sheet Start here
B1: The Econometrics Game: find out which pounds raised the sign-ups
B2: Version 2, September 2026. CRUK confidential, internal use only. No macros: type in the blue cells and everything updates.
B4: The idea, in one picture
B5: Imagine a detective with three years of till receipts. Every week the receipts show how many people signed up for Race for Life.
B6: The detective also knows what happened each week. Which adverts ran. Whether there was a sale. Whether sign-ups were even open.
B7: The detective's job is to work out which of those things caused the sign-ups. That is all econometrics is. Analytic Partners did it for us in 2026 and called it Wave 1. In this game you do it yourself, one block at a time.
B9: How to play
B10: 1. Type only in the blue cells. 2. Each level adds one block to your model and asks for one or two numbers. 3. A check tells you when a number is about right. Green means move on. 4. Stuck? Set Show the answer to Yes.
B12: Two routes
B13: Five minutes | C13: Level 1, then Level 4, then the What if box on Level 5, then Level 8. You will leave knowing the base, the kettle, the halo and the last pound.
B14: Thirty minutes | C14: Levels 1 to 9 in order. Each one builds on the last. Finish with Words, which names every term you have already understood.
B16: Your progress
B17: Level | C17: What you build | D17: The word you learn | E17: Status
B18: Level 1 | C18: The regulars | D18: Baseline | E18: ='Level 1'!C17 -> Keep going
B19: Level 2 | C19: The brakes | D19: Negative driver | E19: ='Level 2'!C17 -> Keep going
B20: Level 3 | C20: The sale | D20: Pull-forward | E20: ='Level 3'!C19 -> Keep going
B21: Level 4 | C21: The kettle: Race for Life adverts | D21: Adstock | E21: ='Level 4'!C20 -> Keep going
B22: Level 5 | C22: Rain on the next field: halo | D22: Halo | E22: ='Level 5'!C21 -> Keep going
B23: Level 6 | C23: Who sang louder: the channel split | D23: Multicollinearity | E23: ='Level 6'!C22 -> Keep going
B24: Level 7 | C24: Is it any good: four tests | D24: R squared, MAPE, holdout | E24: ='Level 7'!C17 -> Keep going
B25: Level 8 | C25: The next pound: the budget game | D25: Marginal return | E25: ='Level 8'!C32 -> Keep going
B26: Level 9 | C26: The long game: brand and Committed Giving | D26: Brand equity | E26: Read and try
B28: Levels done | C28: =COUNTIF(E18:E26,"Level done*")&" of 8" -> 0 of 8
B30: Say this in the room
B31: Econometrics is a detective reading three years of weekly receipts to work out which pounds raised the sign-ups. It can only see what changed.
B33: Where the numbers come from
B34: Analytic Partners, CRUK Wave 1 Econometrics Results (July 2026) and Wave 1 Methodology and Model Documentation (17 July 2026). The weekly figures are AP's own, read from the charts in the results deck: real sign-ups, spend by channel and product, and AP's weekly decomposition of sign-ups by driver, January 2023 to October 2025. The game's answer key is fitted to that decomposition. Sponsorship income is counted at about £90 per sign-up, as AP do.
B35: Built on the Analytic Partners training game. Under the bonnet shows every weekly number and every formula. Words explains every term. Nothing is hidden except the answer key, so the game stays a game.

Sheet Level 1
B1: Level 1: A few hundred people a week sign up whatever we do
B2: The regulars. One number to type. Two minutes.
B4: 1. Look at the picture
B5: This is the real line: how many people signed up for Race for Life each week for nearly three years. The tall spikes are spring. From August to December almost nobody signs up.
B6: Look closely at the quiet months. Even then a few hundred people sign up every week. They already know us. Many of them get our emails.
B7: Your job on this level is to guess how many people sign up in a week when there are no adverts and no sale. That is the first block of any model.
B9: 2. Try: type in the blue cells
B11: People who sign up in a week with no adverts and no sale | D11: Look at the quiet autumn weeks. A number in the hundreds.
B15: 3. Check
B16: Your number | C16: =IF('Level 1'!$C$11="","Type a number",IF('Level 1'!$C$11<Answers!$C$3*(1-Answers!$C$11),"Too low",IF('Level 1'!$C$11>Answers!$C$3*(1+Answers!$C$11),"Too high","About right"))) -> Type a number
B17: This level | C17: =IF(AND(C16="About right"),"Level done. Move on.","Keep going") -> Keep going
B23: 4. What you just learned
B24: Some people would sign up even if we did nothing. The model counts them first, before it gives any credit to adverts.
B25: Economists call this block the baseline. For Race for Life it is small: under a thousand a week. Almost every other sign-up was caused by something we did.
B26: Wave 1 found this block came from two things: people who already consider Cancer Research UK, and our own emails.
B28: Say this in the room
B29: Race for Life has a small base of a few hundred sign-ups a week. Nearly every other sign-up was caused by something we did.
B31: Show the answer? Try a few numbers first. | C31: No
B32: Wave 1 answer: sign-ups a week | C32: =IF(C31="Yes",Answers!C3,"")
B36: Next
B37: Go to Level 2. Some blocks pull sign-ups down, not up.

Sheet Level 2
B1: Level 2: A dearer entry fee and a shut sign-up window cost sign-ups
B2: The brakes. Blocks can pull down as well as push up.
B4: 1. Look at the picture
B5: Some things push sign-ups up. Some pull them down. The price of entry pulls down. So does the sign-up window being shut in the autumn.
B6: A model needs the pulling-down blocks too. Without them it would give the adverts credit for sign-ups that price and timing decided.
B7: Your line will dip below zero in the quiet months after this level. That is fine. The sale and the adverts will lift it back. A model is only judged when every block is in.
B9: 2. Try: type in the blue cells
B11: Sign-ups lost in a typical week to price and the shut window | D11: About the same size as the regulars, pulling the other way.
B15: 3. Check
B16: Your number | C16: =IF('Level 2'!$C$11="","Type a number",IF('Level 2'!$C$11<Answers!$C$4*(1-Answers!$C$11),"Too low",IF('Level 2'!$C$11>Answers!$C$4*(1+Answers!$C$11),"Too high","About right"))) -> Type a number
B17: This level | C17: =IF(AND(C16="About right"),"Level done. Move on.","Keep going") -> Keep going
B23: 4. What you just learned
B24: Drivers can be negative. A dearer entry fee and a shut window both cost sign-ups, and the model measures how many.
B25: Economists call these negative drivers. Price is the classic one. In 2025 entry fees were 12% lower on average, and Wave 1 found that added about 2,500 sign-ups.
B26: Wave 1's price block also does a second job: it tells the model that sign-ups are open in spring and closed in autumn.
B28: Say this in the room
B29: Price pulls sign-ups down. The model measures the brake as well as the accelerator, or it would over-credit the adverts.
B31: Show the answer? Try a few numbers first. | C31: No
B32: Wave 1 answer: sign-ups lost a week | C32: =IF(C31="Yes",Answers!C4,"")
B36: Next
B37: Go to Level 3. The tall spikes are sale weeks.

Sheet Level 3
B1: Level 3: A sale week brings in thousands, and some of them were coming anyway
B2: The sale. The biggest single block, with a twist.
B4: 1. Look at the picture
B5: Look at the tall spikes on the real line. Every one is a discount week. Sales are the biggest single thing that moves sign-ups.
B6: Now look at the week after a sale. It dips. Some people who would have signed up next week signed up early to get the deal.
B7: Type how many extra sign-ups a typical sale week brings. The model already knows which weeks were sale weeks and that the end-of-quarter sales were about twice as strong.
B9: 2. Try: type in the blue cells
B11: Extra sign-ups in a typical sale week | D11: How tall is a spike above the weeks around it? Thousands.
B15: 3. Check
B16: Your number | C16: =IF('Level 3'!$C$11="","Type a number",IF('Level 3'!$C$11<Answers!$C$5*(1-Answers!$C$11),"Too low",IF('Level 3'!$C$11>Answers!$C$5*(1+Answers!$C$11),"Too high","About right"))) -> Type a number
B17: Pattern explained so far | C17: =MAX(0,1-SUMXMY2('Under the bonnet'!$D$6:$D$153,'Under the bonnet'!$AL$6:$AL$153)/DEVSQ('Under the bonnet'!$D$6:$D$153)) -> 0
B18: Target for this level | C18: =Answers!C27 -> 0.47
B19: This level | C19: =IF(AND(C16="About right"),"Level done. Move on.","Keep going") -> Keep going
B23: 4. What you just learned
B24: A sale adds sign-ups. It also moves some sign-ups earlier. The model counts the dip after the sale so it does not over-credit the sale.
B25: Economists call the early sign-ups pull-forward. Wave 1 added it after the first results, and it made the media numbers more honest.
B26: Discount windows explained 21% of 2025 sign-ups. That is the biggest block after the adverts.
B28: Say this in the room
B29: Sale weeks drove a fifth of sign-ups. The dip after each sale is real, and the model counts it.
B31: Show the answer? Try a few numbers first. | C31: No
B32: Wave 1 answer: extra sign-ups in a sale week | C32: =IF(C31="Yes",Answers!C5,"")
B36: Next
B37: Go to Level 4. Now the adverts, and the kettle.

Sheet Level 4
B1: Level 4: Adverts keep working for weeks after they stop, like a kettle stays hot
B2: The kettle. Two numbers: how much, and how long the memory lasts.
B4: 1. Look at the picture
B5: The grey bars on the lower picture are what we spent each week on Race for Life adverts: TV, radio, online video, posters, social and the rest.
B6: Sign-ups do not jump only in the week an advert runs. They carry on for weeks afterwards. Think of a kettle. Switch it off and the water stays hot for a while.
B7: Two numbers to type. First, how many sign-ups every £1,000 brings in total, counting all the weeks it keeps working. Second, the memory: how much of last week's effect is still there this week.
B9: 2. Try: type in the blue cells
B11: Sign-ups from every £1,000 spent, counting every week it keeps working | D11: Somewhere between 5 and 30.
B12: Memory: how much of last week's effect is still there this week | D12: 0% means the advert only works in its own week. 90% means it fades very slowly. Pick from the list.
B13: That is this much sponsorship income for every £1 spent | C13: =IF(C11="","",C11*90/1000) | D13: Wave 1 counts about £90 of sponsorship per sign-up. Their figure: about £1.50 across the three years, £1.66 in 2025 alone.
B15: 3. Check
B16: Sign-ups per £1,000 | C16: =IF('Level 4'!$C$11="","Type a number",IF('Level 4'!$C$11<Answers!$C$6*(1-Answers!$C$11),"Too low",IF('Level 4'!$C$11>Answers!$C$6*(1+Answers!$C$11),"Too high","About right"))) -> Type a number
B17: Memory | C17: =IF('Level 4'!$C$12="","Pick a memory",IF('Level 4'!$C$12<Answers!$C$7-Answers!$C$12,"Too short: the effect fades too fast",IF('Level 4'!$C$12>Answers!$C$7+Answers!$C$12,"Too long: the effect lingers too much","About right"))) -> Pick a memory
B18: Pattern explained so far | C18: =MAX(0,1-SUMXMY2('Under the bonnet'!$D$6:$D$153,'Under the bonnet'!$AM$6:$AM$153)/DEVSQ('Under the bonnet'!$D$6:$D$153)) -> 0
B19: Target for this level | C19: =Answers!C28 -> 0.81
B20: This level | C20: =IF(AND(C16="About right",C17="About right"),"Level done. Move on.","Keep going") -> Keep going
B23: 4. What you just learned
B24: Adverts work in the week they run and keep working after. The memory number says how fast that fades. Economists call the fading adstock.
B25: Judge a campaign in the week it airs and you miss most of what it earned. Wave 1 found the short-term effect lasts up to six months.
B26: Wave 1 found Race for Life adverts returned £1.66 of sponsorship income for every £1 in 2025, and about half of all sign-ups came from them.
B28: Say this in the room
B29: Our adverts keep raising sign-ups for weeks after they stop. Judge a campaign in week one and you miss most of what it earned.
B31: Show the answer? Try a few numbers first. | C31: No
B32: Wave 1 answer: sign-ups per £1,000 | C32: =IF(C31="Yes",Answers!C6,"")
B33: Wave 1 answer: memory | C33: =IF(C31="Yes",Answers!C7,"")
B36: Next
B37: Go to Level 5. Adverts for other causes help Race for Life too.

Sheet Level 5
B1: Level 5: Adverts for other causes water the Race for Life field too
B2: The halo. Rain on one field waters the next field.
B4: 1. Look at the picture
B5: Committed Giving adverts ask people to give monthly. Legacy adverts ask people to remember us in their will. Brand adverts just say who we are. None of them mentions Race for Life.
B6: Yet when they ran, Race for Life sign-ups rose. Rain on one field waters the next field too.
B7: Three numbers to type: how many Race for Life sign-ups every £1,000 of each kind of advert brings. They are small per pound. The spend is large, so they add up.
B9: 2. Try: type in the blue cells
B11: Committed Giving adverts: Race for Life sign-ups per £1,000 | D11: Small. Under 10.
B12: Legacy adverts: Race for Life sign-ups per £1,000 | D12: Small. Under 10.
B13: Brand adverts: Race for Life sign-ups per £1,000 | D13: Smaller still. Under 5.
B15: 3. Check
B16: Committed Giving | C16: =IF('Level 5'!$C$11="","Type a number",IF('Level 5'!$C$11<Answers!$C$8*(1-Answers!$C$11),"Too low",IF('Level 5'!$C$11>Answers!$C$8*(1+Answers!$C$11),"Too high","About right"))) -> Type a number
B17: Legacy | C17: =IF('Level 5'!$C$12="","Type a number",IF('Level 5'!$C$12<Answers!$C$9*(1-Answers!$C$11),"Too low",IF('Level 5'!$C$12>Answers!$C$9*(1+Answers!$C$11),"Too high","About right"))) -> Type a number
B18: Brand | C18: =IF('Level 5'!$C$13="","Type a number",IF('Level 5'!$C$13<Answers!$C$10*(1-Answers!$C$11),"Too low",IF('Level 5'!$C$13>Answers!$C$10*(1+Answers!$C$11),"Too high","About right"))) -> Type a number
B19: Pattern explained so far | C19: =MAX(0,1-SUMXMY2('Under the bonnet'!$D$6:$D$153,'Under the bonnet'!$AN$6:$AN$153)/DEVSQ('Under the bonnet'!$D$6:$D$153)) -> 0
B20: Target for this level | C20: =Answers!C29 -> 0.84
B21: This level | C21: =IF(AND(C16="About right",C17="About right",C18="About right"),"Level done. Move on.","Keep going") -> Keep going
B23: 4. What you just learned
B24: Adverts for one product help another. Economists call this a halo. It is measured from the data, not assumed.
B25: In 2023 the Committed Giving halo was 13% of Race for Life sign-ups. By 2025 it was 5%, because the spend was cut by 42%.
B26: The halo is smaller than it first looked. AP rebuilt it after feedback that it felt too big, and now measure Committed Giving as one block rather than channel by channel.
B28: Say this in the room
B29: Committed Giving adverts were quietly filling Race for Life too. When we cut them, Race for Life felt it.
B31: Show the answer? Try a few numbers first. | C31: No
B32: Wave 1 answer: Committed Giving per £1,000 | C32: =IF(C31="Yes",Answers!C8,"")
B33: Wave 1 answer: Legacy per £1,000 | C33: =IF(C31="Yes",Answers!C9,"")
B34: Wave 1 answer: Brand per £1,000 | C34: =IF(C31="Yes",Answers!C10,"")
B39: What if: the 2025 cut
B40: In 2025 we spent 42% less on Committed Giving adverts than in 2024. Your model puts a number on what that cost Race for Life, January to October, against the same months of 2024.
B41: Race for Life sign-ups lost, your model | C41: =IF(C11="","",SUMIFS('Under the bonnet'!$AB$6:$AB$153,'Under the bonnet'!$B$6:$B$153,2024,'Under the bonnet'!$C$6:$C$153,"<=10")-SUMIFS('Under the bonnet'!$AB$6:$AB$153,'Under the bonnet'!$B$6:$B$153,2025,'Under the bonnet'!$C$6:$C$153,"<=10"))
B42: Race for Life sign-ups lost, Wave 1 | C42: 9139 | D42: AP's waterfall, 2024 to 2025. Second biggest cause of the 7% fall, after the Race for Life cut itself.
B43: Now try: cut Committed Giving adverts by a further | C43: 20 | D43: Type a percentage of the 2025 spend.
B44: Race for Life sign-ups that would go with it, a full year | C44: =IF(C11="","",C11*C43/100*SUMIFS('Under the bonnet'!$J$6:$J$153,'Under the bonnet'!$B$6:$B$153,2025)) | D44: Based on 2025 spend of about £3.2m and your halo number. Sponsorship at £90 a sign-up.
B46: Next
B47: Go to Level 6. Split the Race for Life adverts into channels and meet the catch.

Sheet Level 6
B1: Level 6: When channels run in the same weeks, the model is sure about the group and less sure about each one
B2: Who sang louder. Five numbers, and the honest catch in every media model.
B4: 1. Look at the picture
B5: In Level 4 you treated all Race for Life adverts as one block. Now split them into five: TV, online video, radio, posters, and digital and social together.
B6: Here is the catch. Most of them run in the same weeks. Two people singing the same note: you hear the sound clearly but cannot tell who is louder.
B7: Your Level 4 answer is the guide. AP do exactly this: measure the group first, then split it using the weeks where the channels differ. The checks here are looser on purpose.
B9: 2. Try: type in the blue cells
B11: TV: sign-ups per £1,000 | D11: ="Memory fixed at "&Answers!C16&"%. Sign-ups per £1,000, counting every week." -> Memory fixed at 80%. Sign-ups per £1,000, counting every week.
B12: Online video: sign-ups per £1,000 | D12: ="Memory fixed at "&Answers!C17&"%. Sign-ups per £1,000, counting every week." -> Memory fixed at 80%. Sign-ups per £1,000, counting every week.
B13: Radio: sign-ups per £1,000 | D13: ="Memory fixed at "&Answers!C18&"%. Sign-ups per £1,000, counting every week." -> Memory fixed at 80%. Sign-ups per £1,000, counting every week.
B14: Posters: sign-ups per £1,000 | D14: ="Memory fixed at "&Answers!C19&"%. Sign-ups per £1,000, counting every week." -> Memory fixed at 80%. Sign-ups per £1,000, counting every week.
B15: 3. Check | D15: ="Memory fixed at "&Answers!C20&"%. Sign-ups per £1,000, counting every week." -> Memory fixed at 80%. Sign-ups per £1,000, counting every week.
B16: TV | C16: =IF('Level 6'!$C$11="","Type a number",IF('Level 6'!$C$11<Answers!$E$16*(1-Answers!$C$13),"Too low",IF('Level 6'!$C$11>Answers!$E$16*(1+Answers!$C$13),"Too high","About right"))) -> Type a number
B17: Online video | C17: =IF('Level 6'!$C$12="","Type a number",IF('Level 6'!$C$12<Answers!$E$17*(1-Answers!$C$13),"Too low",IF('Level 6'!$C$12>Answers!$E$17*(1+Answers!$C$13),"Too high","About right"))) -> Type a number
B18: Radio | C18: =IF('Level 6'!$C$13="","Type a number",IF('Level 6'!$C$13<Answers!$E$18*(1-Answers!$C$13),"Too low",IF('Level 6'!$C$13>Answers!$E$18*(1+Answers!$C$13),"Too high","About right"))) -> Type a number
B19: Posters | C19: =IF('Level 6'!$C$14="","Type a number",IF('Level 6'!$C$14<Answers!$E$19*(1-Answers!$C$13),"Too low",IF('Level 6'!$C$14>Answers!$E$19*(1+Answers!$C$13),"Too high","About right"))) -> Type a number
B20: Digital, social and the rest | C20: =IF('Level 6'!$C$15="","Type a number",IF('Level 6'!$C$15<Answers!$E$20*(1-Answers!$C$13),"Too low",IF('Level 6'!$C$15>Answers!$E$20*(1+Answers!$C$13),"Too high","About right"))) -> Type a number
B21: Pattern explained with the split | C21: =MAX(0,1-SUMXMY2('Under the bonnet'!$D$6:$D$153,'Under the bonnet'!$AO$6:$AO$153)/DEVSQ('Under the bonnet'!$D$6:$D$153)) -> 0
B22: This level | C22: =IF(AND(C16="About right",C17="About right",C18="About right",C19="About right",C20="About right"),"Level done. Move on.","Keep going") -> Keep going
B23: 4. What you just learned
B24: Channels that air together are hard to tell apart. Economists call this multicollinearity. It is not a fault in the model. It is a fact about the media plan.
B25: AP handle it by measuring the group first, then splitting it within a range. That is why the group number is firm and each channel comes with a range around it.
B26: Once all five dials are typed, the game uses your split instead of your Level 4 block. Your pattern score barely moves. That is the lesson: the split changes the story, not the fit.
B28: Say this in the room
B29: The group number is firm. The channel split is softer. Quote the range when a decision is close.
B31: Show the answer? Try a few numbers first. | C31: No
B32: Wave 1 answers: TV, video, radio, posters, digital per £1,000 | C32: =IF(C31="Yes",TEXT(Answers!E16,"0.0")&", "&TEXT(Answers!E17,"0.0")&", "&TEXT(Answers!E18,"0.0")&", "&TEXT(Answers!E19,"0.0")&", "&TEXT(Answers!E20,"0.0"),"")
B39: How sure can we be? Three things the data tells us
B40: How often the channels move together. A number near 1 means they rise and fall in the same weeks, so the model struggles to tell them apart. Near 0 means they take turns, which is what a model needs.
B41: TV and online video | C41: =CORREL('Under the bonnet'!$N$6:$N$153,'Under the bonnet'!$O$6:$O$153) -> 0.45332638
B42: TV and radio | C42: =CORREL('Under the bonnet'!$N$6:$N$153,'Under the bonnet'!$P$6:$P$153) -> 0.26010885
B43: Radio and posters | C43: =CORREL('Under the bonnet'!$P$6:$P$153,'Under the bonnet'!$Q$6:$Q$153) -> 0.29151316
B44: Online video and digital | C44: =CORREL('Under the bonnet'!$O$6:$O$153,'Under the bonnet'!$R$6:$R$153) -> 0.50525449
B46: Race for Life TV stopped after 2024. That gave the model two seasons with TV and one without. Changes like that are what let a model tell channels apart. A channel that never changes cannot be measured.
B47: How sure AP were, from their own tests. TV, online video, posters, radio and regional as a group: sure (t-stat 3.1, where above 2 means the link is very unlikely to be luck). Social, search, display, audio and YouTube as a group: very sure (4.6). Posters on their own: the weakest channel, returning about 60p per £1 with a wide range either side.
B49: Next
B50: Go to Level 7. Is your model any good?

Sheet Level 7
B1: Level 7: A good model explains the pattern, misses at random and predicts weeks it never saw
B2: Is it any good? Four questions, your score beside Wave 1's. Nothing to type.
B4: 1. Look at the picture
B5: Your finished model sits on top of the real line. Where the two lines touch, your model has explained that week. Where they part, something is missing or too big.
B6: The lower picture shows the misses week by week. A good model misses a little every week and at random. A model that misses in long runs has forgotten a block.
B8: 2. Check: your model against Wave 1
B9: The test | C9: Yours | D9: Wave 1 | E9: Verdict | F9: What it means in plain words
B10: Pattern explained (R squared) | C10: =MAX(0,1-SUMXMY2('Under the bonnet'!$D$6:$D$153,'Under the bonnet'!$AP$6:$AP$153)/DEVSQ('Under the bonnet'!$D$6:$D$153)) -> 0 | D10: 0.94 | E10: =IF(C10>=0.85,"Good","Keep building") -> Keep building | F10: How much of the weekly up-and-down your model reproduces. AP's guide is above 85%. Wave 1 reached 94%.
B11: Typical weekly miss (MAPE, weeks over 2,000 sign-ups) | C11: =IFERROR(AVERAGE('Under the bonnet'!$BT$6:$BT$153),"") -> 1 | D11: 0.28 | E11: =IF(C11="","",IF(C11<=0.35,"Good","Keep building")) -> Keep building | F11: On an average season week, how far your number is from the real one. Quiet weeks are left out, as AP did, because a miss of 50 on a week of 100 looks like 50%. AP's guide is under 15%. Wave 1 sits at 28%, which AP accept because the seasonal peaks are so sharp.
B12: Are the misses random? (Durbin-Watson) | C12: =IFERROR(SUM('Under the bonnet'!$BS$6:$BS$153)/SUM('Under the bonnet'!$BR$6:$BR$153),"") -> 0.41945497 | D12: 1.51 | E12: =IF(C12="","",IF(AND(C12>=1,C12<=3),"Good","Runs of misses")) -> Runs of misses | F12: Near 2 means the misses are random noise. Well below 1 means the model keeps missing in runs, usually a seasonal block it has not got. Wave 1 scored 1.51. The game's own answer scores about 1.0 because its memory curves are simpler than AP's.
B13: Fit on 2023 to 2024 (the weeks you tuned on) | C13: =MAX(0,1-SUMPRODUCT(('Under the bonnet'!$B$6:$B$153<2025)*('Under the bonnet'!$D$6:$D$153-'Under the bonnet'!$AP$6:$AP$153)^2)/SUMPRODUCT(('Under the bonnet'!$B$6:$B$153<2025)*('Under the bonnet'!$D$6:$D$153-SUMPRODUCT(('Under the bonnet'!$B$6:$B$153<2025)*'Under the bonnet'!$D$6:$D$153)/COUNTIF('Under the bonnet'!$B$6:$B$153,"<2025"))^2)) -> 0 | D13: not shown | E13: =IF(C13>=0.85,"Good","Keep building") -> Keep building | F13: The pattern test on the first two years only.
B14: Holdout: fit on 2025 (weeks a good model predicts) | C14: =MAX(0,1-SUMPRODUCT(('Under the bonnet'!$B$6:$B$153=2025)*('Under the bonnet'!$D$6:$D$153-'Under the bonnet'!$AP$6:$AP$153)^2)/SUMPRODUCT(('Under the bonnet'!$B$6:$B$153=2025)*('Under the bonnet'!$D$6:$D$153-SUMPRODUCT(('Under the bonnet'!$B$6:$B$153=2025)*'Under the bonnet'!$D$6:$D$153)/COUNTIF('Under the bonnet'!$B$6:$B$153,2025))^2)) -> 0 | D14: not shown | E14: =IF(C14>=0.8,"Good","Copied the past, not the pattern") -> Copied the past, not the pattern | F14: A model can copy the past and still be wrong about the future. If the first two years are green and 2025 is red, the model copied the noise, not the pattern. AP test this with holdouts.
B15: Unexplained change, 2024 to 2025 (January to October) | C15: =IFERROR(((SUMIFS('Under the bonnet'!$D$6:$D$153,'Under the bonnet'!$B$6:$B$153,2025,'Under the bonnet'!$C$6:$C$153,"<=10")-SUMIFS('Under the bonnet'!$D$6:$D$153,'Under the bonnet'!$B$6:$B$153,2024,'Under the bonnet'!$C$6:$C$153,"<=10"))-(SUMIFS('Under the bonnet'!$AP$6:$AP$153,'Under the bonnet'!$B$6:$B$153,2025,'Under the bonnet'!$C$6:$C$153,"<=10")-SUMIFS('Under the bonnet'!$AP$6:$AP$153,'Under the bonnet'!$B$6:$B$153,2024,'Under the bonnet'!$C$6:$C$153,"<=10")))/SUMIFS('Under the bonnet'!$D$6:$D$153,'Under the bonnet'!$B$6:$B$153,2024,'Under the bonnet'!$C$6:$C$153,"<=10"),"") -> -0.071310168 | D15: 0.014 | E15: =IF(C15="","",IF(ABS(C15)<=0.05,"Good","Something is missing")) -> Something is missing | F15: Sign-ups fell 7% in 2025. This is the part of that fall your model cannot pin on any block. Wave 1 left 1.4% unexplained, well inside AP's tolerance. Every model has some.
B17: This level | C17: =IF(AND(E10="Good",E13="Good",E14="Good"),"Level done. Move on.","Keep going") -> Keep going
B19: 3. What you just learned
B20: Four questions judge any model. Does it explain most of the weekly up-and-down? How far off is a typical week? Are the misses random? Does it predict weeks it was not shown?
B21: Economists call these R squared, MAPE, Durbin-Watson and the holdout test. Wave 1 scored 94%, 28%, 1.51 and left 1.4% of the 2025 fall unexplained. You can now read that line and know what it means.
B22: Honesty note. The game's own answer, with every dial set to Wave 1's numbers, scores about 89% on pattern explained and 30% on weekly miss. It sits a little under Wave 1 because the game uses one simple memory curve per block where AP fit a curve per channel. The blocks and their sizes are Wave 1's.
B24: Say this in the room
B25: A good model explains most of the weekly pattern, misses at random, predicts weeks it never saw and leaves little of the year-on-year change unexplained. Wave 1 does all four.
B31: Show Wave 1's model on the picture? | C31: No
B36: Next
B37: Go to Level 8. Where should the next pound go?

Sheet Level 8
B1: Level 8: The average pound returned £1.66 but the last pound returned 82p
B2: The next pound. Move money between channels and see what happens. Same total budget.
B4: 1. Look at the picture
B5: The third biscuit never tastes like the first. The first £100,000 on a channel finds the keenest people. The next £100,000 has to persuade harder. So each extra pound earns a little less than the one before.
B6: This table is the real 2025 Race for Life plan, January to October, with the return per £1 that Wave 1 measured for each channel. Type a new spend for any channel in the blue cells. Keep the total the same. Try to beat the 2025 plan.
B8: 2. Try: move the money
B9: Channel | C9: 2025 spend £k | D9: Wave 1 return per £1 | E9: Your spend £k | F9: Lowest allowed | G9: Highest allowed | H9: Plan in use £k | I9: Sign-ups | J9: Income £k | K9: Average return per £1 | L9: Last-pound return per £1 | M9: AP's plan £k
B10: DRTV | C10: 985 | D10: 1.955 | E10: 985 | F10: =ROUND(C10*0.5,0) -> 493 | G10: =ROUND(C10*1.5,0) -> 1478 | H10: =IF($C$26="AP's plan",M10,MIN(G10,MAX(F10,IF(E10="",0,E10)))) -> 985 | I10: =IF(H10<=0,0,(D10*C10*1000/90)/SQRT(C10)*SQRT(H10)) -> 21396.389 | J10: =I10*90/1000 -> 1925.675 | K10: =IF(H10<=0,0,J10/H10) -> 1.955 | L10: =0.5*K10 -> 0.9775 | M10: 1375
B11: Online video (VOD) | C11: 899 | D11: 1.861 | E11: 899 | F11: =ROUND(C11*0.5,0) -> 450 | G11: =ROUND(C11*1.5,0) -> 1349 | H11: =IF($C$26="AP's plan",M11,MIN(G11,MAX(F11,IF(E11="",0,E11)))) -> 899 | I11: =IF(H11<=0,0,(D11*C11*1000/90)/SQRT(C11)*SQRT(H11)) -> 18589.322 | J11: =I11*90/1000 -> 1673.039 | K11: =IF(H11<=0,0,J11/H11) -> 1.861 | L11: =0.5*K11 -> 0.9305 | M11: 769
B12: Radio | C12: 834 | D12: 1.753 | E12: 834 | F12: =ROUND(C12*0.5,0) -> 417 | G12: =ROUND(C12*1.5,0) -> 1251 | H12: =IF($C$26="AP's plan",M12,MIN(G12,MAX(F12,IF(E12="",0,E12)))) -> 834 | I12: =IF(H12<=0,0,(D12*C12*1000/90)/SQRT(C12)*SQRT(H12)) -> 16244.467 | J12: =I12*90/1000 -> 1462.002 | K12: =IF(H12<=0,0,J12/H12) -> 1.753 | L12: =0.5*K12 -> 0.8765 | M12: 667
B13: Paid social | C13: 1063 | D13: 1.591 | E13: 1063 | F13: =ROUND(C13*0.5,0) -> 532 | G13: =ROUND(C13*1.5,0) -> 1595 | H13: =IF($C$26="AP's plan",M13,MIN(G13,MAX(F13,IF(E13="",0,E13)))) -> 1063 | I13: =IF(H13<=0,0,(D13*C13*1000/90)/SQRT(C13)*SQRT(H13)) -> 18791.478 | J13: =I13*90/1000 -> 1691.233 | K13: =IF(H13<=0,0,J13/H13) -> 1.591 | L13: =0.5*K13 -> 0.7955 | M13: 1077
B14: Regional | C14: 748 | D14: 1.71 | E14: 748 | F14: =ROUND(C14*0.5,0) -> 374 | G14: =ROUND(C14*1.5,0) -> 1122 | H14: =IF($C$26="AP's plan",M14,MIN(G14,MAX(F14,IF(E14="",0,E14)))) -> 748 | I14: =IF(H14<=0,0,(D14*C14*1000/90)/SQRT(C14)*SQRT(H14)) -> 14212 | J14: =I14*90/1000 -> 1279.08 | K14: =IF(H14<=0,0,J14/H14) -> 1.71 | L14: =0.5*K14 -> 0.855 | M14: 460
B15: Posters (OOH) | C15: 521 | D15: 0.538 | E15: 521 | F15: =ROUND(C15*0.5,0) -> 261 | G15: =ROUND(C15*1.5,0) -> 782 | H15: =IF($C$26="AP's plan",M15,MIN(G15,MAX(F15,IF(E15="",0,E15)))) -> 521 | I15: =IF(H15<=0,0,(D15*C15*1000/90)/SQRT(C15)*SQRT(H15)) -> 3114.4222 | J15: =I15*90/1000 -> 280.298 | K15: =IF(H15<=0,0,J15/H15) -> 0.538 | L15: =0.5*K15 -> 0.269 | M15: 320
B16: Digital audio | C16: 458 | D16: 1.708 | E16: 458 | F16: =ROUND(C16*0.5,0) -> 229 | G16: =ROUND(C16*1.5,0) -> 687 | H16: =IF($C$26="AP's plan",M16,MIN(G16,MAX(F16,IF(E16="",0,E16)))) -> 458 | I16: =IF(H16<=0,0,(D16*C16*1000/90)/SQRT(C16)*SQRT(H16)) -> 8691.8222 | J16: =I16*90/1000 -> 782.264 | K16: =IF(H16<=0,0,J16/H16) -> 1.708 | L16: =0.5*K16 -> 0.854 | M16: 658
B17: Display | C17: 442 | D17: 1.74 | E17: 442 | F17: =ROUND(C17*0.5,0) -> 221 | G17: =ROUND(C17*1.5,0) -> 663 | H17: =IF($C$26="AP's plan",M17,MIN(G17,MAX(F17,IF(E17="",0,E17)))) -> 442 | I17: =IF(H17<=0,0,(D17*C17*1000/90)/SQRT(C17)*SQRT(H17)) -> 8545.3333 | J17: =I17*90/1000 -> 769.08 | K17: =IF(H17<=0,0,J17/H17) -> 1.74 | L17: =0.5*K17 -> 0.87 | M17: 552
B18: Paid search | C18: 318 | D18: 1.7 | E18: 318 | F18: =ROUND(C18*0.5,0) -> 159 | G18: =ROUND(C18*1.5,0) -> 477 | H18: =IF($C$26="AP's plan",M18,MIN(G18,MAX(F18,IF(E18="",0,E18)))) -> 318 | I18: =IF(H18<=0,0,(D18*C18*1000/90)/SQRT(C18)*SQRT(H18)) -> 6006.6667 | J18: =I18*90/1000 -> 540.6 | K18: =IF(H18<=0,0,J18/H18) -> 1.7 | L18: =0.5*K18 -> 0.85 | M18: 375
B19: YouTube | C19: 121 | D19: 1.85 | E19: 121 | F19: =ROUND(C19*0.5,0) -> 61 | G19: =ROUND(C19*1.5,0) -> 182 | H19: =IF($C$26="AP's plan",M19,MIN(G19,MAX(F19,IF(E19="",0,E19)))) -> 121 | I19: =IF(H19<=0,0,(D19*C19*1000/90)/SQRT(C19)*SQRT(H19)) -> 2487.2222 | J19: =I19*90/1000 -> 223.85 | K19: =IF(H19<=0,0,J19/H19) -> 1.85 | L19: =0.5*K19 -> 0.925 | M19: 150
B20: Telemarketing | C20: 102 | D20: 1.2 | E20: 102 | F20: =ROUND(C20*0.5,0) -> 51 | G20: =ROUND(C20*1.5,0) -> 153 | H20: =IF($C$26="AP's plan",M20,MIN(G20,MAX(F20,IF(E20="",0,E20)))) -> 102 | I20: =IF(H20<=0,0,(D20*C20*1000/90)/SQRT(C20)*SQRT(H20)) -> 1360 | J20: =I20*90/1000 -> 122.4 | K20: =IF(H20<=0,0,J20/H20) -> 1.2 | L20: =0.5*K20 -> 0.6 | M20: 71
B21: Direct mail | C21: 40 | D21: 1.9 | E21: 40 | F21: =ROUND(C21*0.5,0) -> 20 | G21: =ROUND(C21*1.5,0) -> 60 | H21: =IF($C$26="AP's plan",M21,MIN(G21,MAX(F21,IF(E21="",0,E21)))) -> 40 | I21: =IF(H21<=0,0,(D21*C21*1000/90)/SQRT(C21)*SQRT(H21)) -> 844.44444 | J21: =I21*90/1000 -> 76 | K21: =IF(H21<=0,0,J21/H21) -> 1.9 | L21: =0.5*K21 -> 0.95 | M21: 57
B22: Door drops | C22: 22 | D22: 2 | E22: 22 | F22: =ROUND(C22*0.5,0) -> 11 | G22: =ROUND(C22*1.5,0) -> 33 | H22: =IF($C$26="AP's plan",M22,MIN(G22,MAX(F22,IF(E22="",0,E22)))) -> 22 | I22: =IF(H22<=0,0,(D22*C22*1000/90)/SQRT(C22)*SQRT(H22)) -> 488.88889 | J22: =I22*90/1000 -> 44 | K22: =IF(H22<=0,0,J22/H22) -> 2 | L22: =0.5*K22 -> 1 | M22: 21
B23: Total | C23: =SUM(C10:C22) -> 6553 | E23: =SUM(E10:E22) -> 6553 | H23: =SUM(H10:H22) -> 6553 | I23: =SUM(I10:I22) -> 120772.46 | J23: =SUM(J10:J22) -> 10869.521 | K23: =J23/H23 -> 1.6587091 | L23: =0.5*K23 -> 0.82935457 | M23: =SUM(M10:M22) -> 6552
B24: Sign-ups use a simple curve: double the spend and you get 41% more sign-ups, not double. Each channel's curve is set so that the 2025 plan gives exactly Wave 1's measured return. AP's real curves differ by channel, so their optimised plan (last column) gained 12,300 sign-ups with them and only about 600 here. The direction is the lesson: money moves towards the channels whose last pound still earns the most.
B26: Whose plan is on the picture? | C26: Mine | D26: Switch to AP's plan to see where they moved the money: out of radio, posters, regional and video, into DRTV, audio and display.
B27: Budget check | C27: =IF(ABS(H23-C23)<=10,"Same total. Good.",IF(H23>C23,"Over budget by £"&TEXT(H23-C23,"#,##0")&"k","Under budget by £"&TEXT(C23-H23,"#,##0")&"k")) -> Same total. Good.
B28: Sign-ups from the 2025 plan | C28: =SUMPRODUCT(D10:D22,C10:C22)*1000/90 -> 120772.46 | D28: Wave 1: 122,189 Race for Life sign-ups from Race for Life media in 2025 (this table covers the thirteen channels with a 2025 return).
B29: Sign-ups from the plan in use | C29: =I23 -> 120772.46
B30: Extra sign-ups you found | C30: =C29-C28 -> 0 | D30: AP's optimiser found 12,300 extra sign-ups (£1.12m) on the same budget with their curves. The most this table can find is about 2,000. Beat 1,000 and you have the idea.
B31: Extra income, £k | C31: =C30*90/1000 -> 0
B32: This level | C32: =IF(AND(C30>=1000,ABS(H23-C23)<=10),"Level done. Move on.",IF(C30>0,"Keep going: find 1,000 more","Keep going")) -> Keep going
B34: 4. What you just learned
B35: Each extra pound earns a little less than the one before. Economists call this diminishing returns. The return on the very last pound is the marginal return.
B36: Wave 1 found the average pound of Race for Life media returned £1.66 in 2025, but the last pound returned 82p. Growth decisions need the last-pound number, not the average. Moving money between channels was worth about £1.1m on the same budget.
B37: Posters returned 60p per £1 in the short term, the weakest channel. Over three years, once the slow brand effect is counted, every channel earns a little more. That is Level 9.
B39: Say this in the room
B40: The average pound returned £1.66 but the last pound returned 82p. Moving money between channels is worth about £1.1m before we add a single pound.
B42: Next
B43: Go to Level 9. The long game: brand, consideration and Committed Giving.

Sheet Level 9
B1: Level 9: Some of today's sign-ups come from adverts people saw years ago
B2: The long game. Brand consideration, and why Committed Giving looks so cheap on paper.
B4: 1. Look at the picture
B5: The line on the picture is brand consideration: the share of people who say they would consider supporting Cancer Research UK. It moves slowly. The bars are everything we spent on media each week, across every cause.
B6: Wave 1 traced 18.8% of today's consideration back to past media. That stock is our brand equity. It is slipping by about a quarter of a point a year.
B7: Consideration then turns into sign-ups over the following three years. That is the long-term effect, and it sits on top of the short-term returns you met in Level 8.
B9: 2. Try: the long-term multiplier
B11: Extra long-term media, £ millions a year | C11: 1 | D11: Wave 1: each extra £1m lifts consideration by about 0.4 points, over one to two years.
B12: Consideration gained, percentage points | C12: =IF(C11="","",C11*0.4) -> 0.4
B13: Against the yearly drift of | C13: -0.25 | D13: Consideration falls about 0.25 points a year without extra investment.
B14: Race for Life media: £1 returns in the short term | C14: 1.66
B15: Race for Life media: £1 returns over three years | C15: =C14*1.21 -> 2.0086 | D15: Wave 1 multiplier 1.21 for Race for Life, 1.04 for Committed Giving. Posters and TV carry the biggest long-term share.
B17: 3. Committed Giving: why 9p per £1 is not the whole story
B18: Wave 1 also modelled new Committed Givers, the people who start a monthly gift. Marketing drove about 73% of them. Yet the return looks tiny: 9p to 20p per £1.
B19: The reason is what the model counts. It counts only brand new givers, at roughly £300 of income each in the modelled window. It does not count the years of giving that follow, and it does not count the givers that adverts stop from leaving.
C21: FY23/24 | D21: FY24/25 | E21: FY25/26 to Oct
B22: New Committed Givers | C22: 12006 | D22: 7622 | E22: 2993
B23: Of which marketing drove | C23: 8568 | D23: 5158 | E23: 2822
B24: Committed Giving media spend, £m | C24: 8.4 | D24: 4.1 | E24: 1.2
B25: Return per £1 on that spend, short term | C25: 0.18 | D25: 0.14 | E25: 0.2
B27: Your assumption: years a new giver keeps giving | C27: 3 | D27: Not a Wave 1 finding. Your own guess, to see what it does to the number.
B28: FY25/26 return per £1 if every year counted the same | C28: =IF(C27="","",E25*C27) -> 0.6 | D28: A simple multiplication, to show why AP say the Committed Giving return is understated. Wave 2 will measure it properly.
B30: 4. What you just learned
B31: Adverts do two jobs. They raise sign-ups now, and they raise the share of people who would consider us at all. Economists call the second job brand equity, and Wave 1 measures it through consideration.
B32: Counting the long-term effect takes Race for Life media from £1.66 to £2.01 per pound. Committed Giving looks cheap because the model only counts the first gift of brand new givers.
B33: Cutting Committed Giving media by nearly half cost about 23% of new givers in FY25/26, and inflation cost about the same again. Two separate causes, one falling line.
B35: Say this in the room
B36: Nearly a fifth of the people who consider us do so because of adverts they saw years ago. The short-term return is the floor, not the ceiling.
B38: Next
B39: You have built the whole model. Go to Words for the ladder of every term, or back to Start here to see your progress.

Sheet Words
B1: Words: every term, climbed one rung at a time
B2: The everyday picture first, then what it meant in Wave 1, then the sentence you can say out loud. The word itself comes last.
B4: The word | C4: The everyday picture | D4: What it meant in Wave 1 | E4: Say this in the room
B5: Econometrics (Level 1) | C5: A detective with three years of weekly till receipts, working out which adverts raised the money. The detective infers. It never witnesses. | D5: Analytic Partners read 148 weeks of Race for Life sign-ups against everything that happened each week, and measured what each thing was worth. | E5: Econometrics is a detective reading three years of weekly receipts to work out which pounds raised the sign-ups.
B6: Baseline (Level 1) | C6: The customers who walk into a shop because it is there and open. The sign-ups we would still get with every advert switched off. | D6: Small for Race for Life: a few hundred a week, from people who already consider us and from our own emails. AP say the true base is close to zero. | E6: The base is what we would get with the adverts off. Everything above it is what we caused.
B7: Driver (Levels 1 to 6) | C7: Anything that can move sign-ups up or down. An advert, a sale, the price, the time of year, even inflation. | D7: AP tested 18 marketing drivers and six non-marketing ones and kept those with a reliable link. Weather, PR and website outages had none. | E7: A driver is anything the model found that moves sign-ups.
B8: Negative driver (Level 2) | C8: A brake. A dearer ticket means fewer people buy it. | D8: Price and the closed autumn window pull sign-ups down. A 12% lower entry fee in 2025 added about 2,500 sign-ups. | E8: Price pulls sign-ups down, and the model measures the brake as well as the accelerator.
B9: Response (Levels 1 to 6) | C9: The exchange rate. How many sign-ups one unit of a driver buys: one sale week, or £1,000 of adverts. | D9: This is the number you type on each level. AP estimate it from the weekly data, with a range either side. | E9: The response is the exchange rate between a driver and sign-ups.
B10: Pull-forward (Level 3) | C10: A January sale. People who were going to buy in February buy in January instead, so February is quiet. | D10: Fewer sign-ups in the weeks after a discount window closed. AP added this after the first results so that sales were not over-credited. | E10: Discounts bring sign-ups forward as well as adding new ones. The dip afterwards is real.
B11: Adstock (Level 4) | C11: A kettle. Switch it off and the water stays hot for a while. Media heat fades over weeks, not minutes. | D11: Each block has a memory. The short-term effect of Race for Life adverts lasts up to six months. | E11: Our adverts keep raising sign-ups for weeks after they stop, and the model measures how fast that fades.
B12: Incremental (Level 4) | C12: The part of the spike above the base. Only the sign-ups the advert caused, not the ones that happened while it was on. | D12: About half of Race for Life sign-ups were incremental to Race for Life media in 2025. | E12: Incremental means the sign-ups the advert caused, not the sign-ups that happened while it was on.
B13: ROI, return per £1 (Levels 4 and 8) | C13: Income earned per pound of adverts. £1.66 back for every £1 in. | D13: Sponsorship income only, about £90 per sign-up. Not entry fees, not Gift Aid, and only new sign-ups. | E13: Every £1 of Race for Life media returned £1.66 of sponsorship income in 2025.
B14: Halo (Level 5) | C14: Rain on one field waters the next field too. Adverts for one product raise sign-ups for another. | D14: Committed Giving media was 13% of Race for Life sign-ups in 2023 and 5% in 2025. Legacy media added 6 to 8%. Measured, not assumed. | E14: Committed Giving adverts were quietly filling Race for Life too. That is the halo.
B15: Multicollinearity (Level 6) | C15: Two people singing the same note. You hear the sound but cannot tell who is louder. | D15: Most Race for Life channels air in the same weeks. AP measure the group first, then split it using the weeks where channels differ. | E15: When channels air together the model is sure about the group and less sure about each channel.
... B26: Long-term multiplier (Level 9) | C26: The slow second job of an advert: making more people consider us at all, which turns into sign-ups over three years. | D26: 1.21 for Race for Life media (£1.66 becomes £2.01) and 1.04 for Committed Giving. Posters and TV carry the biggest share. | E26: Counting the long-term effect takes Race for Life media from £1.66 to £2.01 per pound.
B28: Four pictures
B29: Each picture is one idea. The data under them is illustrative, built to show the shape, not Wave 1 figures.
B71: Data for the pictures (illustrative)
B72: Week | C72: Advert on air | D72: Sign-ups it causes (60% memory) | F72: Spend £k | G72: Income £k | H72: Income if every pound earned like the first | J72: Week | K72: Base | L72: Economy | M72: TV | N72: Radio | O72: Sale | Q72: Year | R72: Committed Giving media £m | S72: Race for Life sign-ups from its halo
B73: 1 | C73: 100 | D73: 100 | F73: 0 | G73: 0 | H73: 0 | J73: 1 | K73: 1 | L73: 0 | M73: 0 | N73: 0 | O73: 0 | Q73: 2023 | R73: 8.3 | S73: 30778
B74: 2 | C74: 100 | D74: 160 | F74: 100 | G74: 525 | H74: 330 | J74: 2 | K74: 1 | L74: 0 | M74: 0 | N74: 0 | O74: 0 | Q74: 2024 | R74: 6.6 | S74: 23325
B75: 3 | C75: 100 | D75: 196 | F75: 200 | G75: 742 | H75: 660 | J75: 3 | K75: 1 | L75: 0 | M75: 0 | N75: 0 | O75: 0 | Q75: 2025 to Oct | R75: 3.2 | S75: 12178
B76: 4 | C76: 0 | D76: 118 | F76: 300 | G76: 909 | H76: 990 | J76: 4 | K76: 1 | L76: 1 | M76: 0 | N76: 0 | O76: 0
B77: 5 | C77: 0 | D77: 71 | F77: 400 | G77: 1050 | H77: 1320 | J77: 5 | K77: 1 | L77: 1 | M77: 0 | N77: 0 | O77: 0
B78: 6 | C78: 0 | D78: 42 | F78: 500 | G78: 1174 | H78: 1650 | J78: 6 | K78: 1 | L78: 1 | M78: 0 | N78: 0 | O78: 0
B79: 7 | C79: 0 | D79: 25 | F79: 600 | G79: 1286 | H79: 1980 | J79: 7 | K79: 1 | L79: 1 | M79: 1 | N79: 0 | O79: 0
B80: 8 | C80: 0 | D80: 15 | F80: 700 | G80: 1389 | H80: 2310 | J80: 8 | K80: 1 | L80: 1 | M80: 1 | N80: 0 | O80: 0
B81: 9 | C81: 0 | D81: 9 | F81: 800 | G81: 1485 | H81: 2640 | J81: 9 | K81: 1 | L81: 1 | M81: 1 | N81: 0 | O81: 0
B82: 10 | C82: 0 | D82: 5 | F82: 900 | G82: 1575 | H82: 2970 | J82: 10 | K82: 1 | L82: 1 | M82: 0 | N82: 0 | O82: 0
B83: 11 | C83: 0 | D83: 3 | F83: 1000 | G83: 1660 | H83: 3300 | J83: 11 | K83: 1 | L83: 1 | M83: 0 | N83: 0 | O83: 0
B84: 12 | C84: 0 | D84: 2 | J84: 12 | K84: 1 | L84: 1 | M84: 1 | N84: 1 | O84: 0
B85: 13 | C85: 0 | D85: 1 | J85: 13 | K85: 1 | L85: 1 | M85: 1 | N85: 1 | O85: 0
B86: 14 | C86: 0 | D86: 1 | J86: 14 | K86: 1 | L86: 1 | M86: 1 | N86: 1 | O86: 0
B87: 15 | C87: 0 | D87: 0 | J87: 15 | K87: 1 | L87: 1 | M87: 0 | N87: 0 | O87: 0
B88: 16 | C88: 0 | D88: 0 | J88: 16 | K88: 1 | L88: 1 | M88: 0 | N88: 0 | O88: 0
J89: 17 | K89: 1 | L89: 1 | M89: 1 | N89: 1 | O89: 1
J90: 18 | K90: 1 | L90: 1 | M90: 1 | N90: 1 | O90: 1
J91: 19 | K91: 1 | L91: 1 | M91: 1 | N91: 1 | O91: 1
J92: 20 | K92: 1 | L92: 1 | M92: 0 | N92: 0 | O92: 0
J93: 21 | K93: 1 | L93: 1 | M93: 0 | N93: 0 | O93: 0
...

Sheet Under the bonnet
A1: Under the bonnet: every weekly number and every formula the game uses. Nothing is hidden.
A2: Columns A to D and the AP columns are Analytic Partners' Wave 1 weekly figures, read from the charts in their July 2026 results deck. Everything else is a formula that points at the blue cells on the level tabs. Click any cell to see how it is built. Spend is in thousands of pounds.
A3: Shape columns: AP's weekly line for that block divided by its typical week, so that your dial times the shape gives your block. Adstock: this week's spend plus memory times last week's total.
A5: Week starting | B5: Year | C5: Month | D5: Real sign-ups | E5: Shape: regulars | F5: Shape: brakes | G5: Shape: sale | H5: RFL adverts £k | I5: RFL adstock | J5: Committed Giving adverts £k | K5: Legacy adverts £k | L5: Brand adverts £k | M5: Brand adstock | N5: TV £k | O5: Online video £k | P5: Radio £k | Q5: Posters £k | R5: Digital and rest £k | S5: TV adstock | T5: Online video adstock | U5: Radio adstock | V5: Posters adstock | W5: Digital adstock | X5: Your block 1: regulars | Y5: Your block 2: brakes | Z5: Your block 3: sale | AA5: Your block 4: RFL adverts | AB5: Your block 5: CG halo | AC5: Your block 5: Legacy halo | AD5: Your block 5: Brand adverts | AE5: Your block 6: TV | AF5: Your block 6: Online video | AG5: Your block 6: Radio | AH5: Your block 6: Posters | AI5: Your block 6: Digital and rest | AJ5: Your model after level 1 | AK5: Your model after level 2 | AL5: Your model after level 3 | AM5: Your model after level 4 | AN5: Your model after level 5 | AO5: Your model after level 6 | AP5: Your final model | AQ5: AP block: regulars | AR5: AP block: brakes | AS5: AP block: sale | AT5: AP block: RFL adverts | AU5: AP block: CG halo | AV5: AP block: Legacy halo | AW5: AP block: Brand adverts | AX5: AP block: TV | AY5: AP block: Online video | AZ5: AP block: Radio | BA5: AP block: Posters | BB5: AP block: Digital and rest | BC5: Wave 1 model | BD5: Wave 1 after level 1 | BE5: Wave 1 after level 2 | BF5: Wave 1 after level 3 | BG5: Wave 1 after level 4 | BH5: Wave 1 after level 5 | BI5: Wave 1 after level 6 | BJ5: Answer line L1 | BK5: Answer line L2 | BL5: Answer line L3 | BM5: Answer line L4 | BN5: Answer line L5 | BO5: Answer line L6 | BP5: Answer line L7 | BQ5: Miss (real minus yours) | BR5: Miss squared | BS5: Miss change squared | BT5: Weekly % miss (weeks over 2,000) | BU5: Real new Committed Givers | BV5: Brand consideration | BW5: All CRUK media £k | BX5: Your block 4 on this level 4 chart | BY5: RFL adverts £k (for chart) | BZ5: Sale weeks (for chart) | CA5: Your halo blocks | CB5: Your split blocks
A6: 44934 | B6: =YEAR(A6) -> 2023 | C6: =MONTH(A6) -> 1 | D6: 15469 | E6: 0.6228 | F6: 0.059 | G6: 0.7291 | H6: 112.9 | I6: =H6 -> 112.9 | J6: 480.94 | K6: 88.32 | L6: 93.95 | M6: =L6 -> 93.95 | N6: 0 | O6: 0 | P6: 53.8 | Q6: 0 | R6: 43.63 | S6: =N6 -> 0 | T6: =O6 -> 0 | U6: =P6 -> 53.8 | V6: =Q6 -> 0 | W6: =R6 -> 43.63 | X6: =IF('Level 1'!$C$11="",0,'Level 1'!$C$11)*E6 -> 0 | Y6: =-IF('Level 2'!$C$11="",0,'Level 2'!$C$11)*F6 -> 0 | Z6: =IF('Level 3'!$C$11="",0,'Level 3'!$C$11)*G6 -> 0 | AA6: =IF('Level 4'!$C$11="",0,'Level 4'!$C$11)*(1-'Level 4'!$C$12/100)*I6 -> 0 | AB6: =IF('Level 5'!$C$11="",0,'Level 5'!$C$11)*J6 -> 0 | AC6: =IF('Level 5'!$C$12="",0,'Level 5'!$C$12)*K6 -> 0 | AD6: =IF('Level 5'!$C$13="",0,'Level 5'!$C$13)*(1-Answers!$C$14/100)*M6 -> 0 | AE6: =IF('Level 6'!$C$11="",0,'Level 6'!$C$11)*(1-Answers!$C$16/100)*S6 -> 0 | AF6: =IF('Level 6'!$C$12="",0,'Level 6'!$C$12)*(1-Answers!$C$17/100)*T6 -> 0 | AG6: =IF('Level 6'!$C$13="",0,'Level 6'!$C$13)*(1-Answers!$C$18/100)*U6 -> 0 | AH6: =IF('Level 6'!$C$14="",0,'Level 6'!$C$14)*(1-Answers!$C$19/100)*V6 -> 0 | AI6: =IF('Level 6'!$C$15="",0,'Level 6'!$C$15)*(1-Answers!$C$20/100)*W6 -> 0 | AJ6: =X6 -> 0 | AK6: =X6+Y6 -> 0 | AL6: =AK6+Z6 -> 0 | AM6: =AL6+AA6 -> 0 | AN6: =AM6+AB6+AC6+AD6 -> 0 | AO6: =AL6+AE6+AF6+AG6+AH6+AI6+AB6+AC6+AD6 -> 0 | AP6: =IF(Answers!$C$22="Yes",AO6,AN6) -> 0 | AQ6: 545.3 | AR6: -56.2 | AS6: 5539.2 | AT6: 279.3 | AU6: 1858.5 | AV6: 325.9 | AW6: 169.5 | AX6: 0 | AY6: 0 | AZ6: 141.1 | BA6: 0 | BB6: 138.2 | BC6: =AQ6+AR6+AS6+AT6+AU6+AV6+AW6 -> 8661.5 | BD6: =AQ6 -> 545.3 | BE6: =AQ6+AR6 -> 489.1 | BF6: =BE6+AS6 -> 6028.3 | BG6: =BF6+AT6 -> 6307.6 | BH6: =BG6+AU6+AV6+AW6 -> 8661.5 | BI6: =BC6 -> 8661.5 | BJ6: =IF('Level 1'!$C$31="Yes",BD6,AJ6) -> 0 | BK6: =IF('Level 2'!$C$31="Yes",BE6,AK6) -> 0 | BL6: =IF('Level 3'!$C$31="Yes",BF6,AL6) -> 0 | BM6: =IF('Level 4'!$C$31="Yes",BG6,AM6) -> 0 | BN6: =IF('Level 5'!$C$31="Yes",BH6,AN6) -> 0 | BO6: =IF('Level 6'!$C$31="Yes",BI6,AO6) -> 0 | BP6: =IF('Level 7'!$C$31="Yes",BC6,AP6) -> 0 | BQ6: =D6-AP6 -> 15469 | BR6: =BQ6^2 -> 239289961 | BS6: 0 | BT6: =IF(D6>2000,ABS(BQ6)/D6,"") -> 1 | BU6: 353 | BV6: 0.5182 | BW6: 848.3 | BX6: =AA6 -> 0 | BY6: =H6 -> 112.9 | BZ6: =Z6 -> 0 | CA6: =AB6+AC6+AD6 -> 0 | CB6: =AE6+AF6+AG6+AH6+AI6 -> 0
A7: 44941 | B7: =YEAR(A7) -> 2023 | C7: =MONTH(A7) -> 1 | D7: 13743 | E7: 0.6228 | F7: 0.0043 | G7: 0.7291 | H7: 127.61 | I7: =H7+'Level 4'!$C$12/100*I6 -> 127.61 | J7: 459.63 | K7: 73.57 | L7: 85.96 | M7: =L7+Answers!$C$14/100*M6 -> 142.33 | N7: 0 | O7: 0 | P7: 34.89 | Q7: 0 | R7: 78.97 | S7: =N7+Answers!$C$16/100*S6 -> 0 | T7: =O7+Answers!$C$17/100*T6 -> 0 | U7: =P7+Answers!$C$18/100*U6 -> 77.93 | V7: =Q7+Answers!$C$19/100*V6 -> 0 | W7: =R7+Answers!$C$20/100*W6 -> 113.874 | X7: =IF('Level 1'!$C$11="",0,'Level 1'!$C$11)*E7 -> 0 | Y7: =-IF('Level 2'!$C$11="",0,'Level 2'!$C$11)*F7 -> 0 | Z7: =IF('Level 3'!$C$11="",0,'Level 3'!$C$11)*G7 -> 0 | AA7: =IF('Level 4'!$C$11="",0,'Level 4'!$C$11)*(1-'Level 4'!$C$12/100)*I7 -> 0 | AB7: =IF('Level 5'!$C$11="",0,'Level 5'!$C$11)*J7 -> 0 | AC7: =IF('Level 5'!$C$12="",0,'Level 5'!$C$12)*K7 -> 0 | AD7: =IF('Level 5'!$C$13="",0,'Level 5'!$C$13)*(1-Answers!$C$14/100)*M7 -> 0 | AE7: =IF('Level 6'!$C$11="",0,'Level 6'!$C$11)*(1-Answers!$C$16/100)*S7 -> 0 | AF7: =IF('Level 6'!$C$12="",0,'Level 6'!$C$12)*(1-Answers!$C$17/100)*T7 -> 0 | AG7: =IF('Level 6'!$C$13="",0,'Level 6'!$C$13)*(1-Answers!$C$18/100)*U7 -> 0 | AH7: =IF('Level 6'!$C$14="",0,'Level 6'!$C$14)*(1-Answers!$C$19/100)*V7 -> 0 | AI7: =IF('Level 6'!$C$15="",0,'Level 6'!$C$15)*(1-Answers!$C$20/100)*W7 -> 0 | AJ7: =X7 -> 0 | AK7: =X7+Y7 -> 0 | AL7: =AK7+Z7 -> 0 | AM7: =AL7+AA7 -> 0 | AN7: =AM7+AB7+AC7+AD7 -> 0 | AO7: =AL7+AE7+AF7+AG7+AH7+AI7+AB7+AC7+AD7 -> 0 | AP7: =IF(Answers!$C$22="Yes",AO7,AN7) -> 0 | AQ7: 545.3 | AR7: -4.1 | AS7: 5539.2 | AT7: 561.4 | AU7: 1776.4 | AV7: 271.5 | AW7: 110.2 | AX7: 0 | AY7: 0 | AZ7: 211.4 | BA7: 0 | BB7: 349.9 | BC7: =AQ7+AR7+AS7+AT7+AU7+AV7+AW7 -> 8799.9 | BD7: =AQ7 -> 545.3 | BE7: =AQ7+AR7 -> 541.2 | BF7: =BE7+AS7 -> 6080.4 | BG7: =BF7+AT7 -> 6641.8 | BH7: =BG7+AU7+AV7+AW7 -> 8799.9 | BI7: =BC7 -> 8799.9 | BJ7: =IF('Level 1'!$C$31="Yes",BD7,AJ7) -> 0 | BK7: =IF('Level 2'!$C$31="Yes",BE7,AK7) -> 0 | BL7: =IF('Level 3'!$C$31="Yes",BF7,AL7) -> 0 | BM7: =IF('Level 4'!$C$31="Yes",BG7,AM7) -> 0 | BN7: =IF('Level 5'!$C$31="Yes",BH7,AN7) -> 0 | BO7: =IF('Level 6'!$C$31="Yes",BI7,AO7) -> 0 | BP7: =IF('Level 7'!$C$31="Yes",BC7,AP7) -> 0 | BQ7: =D7-AP7 -> 13743 | BR7: =BQ7^2 -> 188870049 | BS7: =(BQ7-BQ6)^2 -> 2979076 | BT7: =IF(D7>2000,ABS(BQ7)/D7,"") -> 1 | BU7: 396 | BV7: 0.5182 | BW7: 841.2 | BX7: =AA7 -> 0 | BY7: =H7 -> 127.61 | BZ7: =Z7 -> 0 | CA7: =AB7+AC7+AD7 -> 0 | CB7: =AE7+AF7+AG7+AH7+AI7 -> 0
A8: 44948 | B8: =YEAR(A8) -> 2023 | C8: =MONTH(A8) -> 1 | D8: 11484 | E8: 0.6149 | F8: -0.0097 | G8: 0.7291 | H8: 141.44 | I8: =H8+'Level 4'!$C$12/100*I7 -> 141.44 | J8: 160.45 | K8: 317.76 | L8: 69.65 | M8: =L8+Answers!$C$14/100*M7 -> 155.048 | N8: 0 | O8: 0 | P8: 31.23 | Q8: 0 | R8: 98.72 | S8: =N8+Answers!$C$16/100*S7 -> 0 | T8: =O8+Answers!$C$17/100*T7 -> 0 | U8: =P8+Answers!$C$18/100*U7 -> 93.574 | V8: =Q8+Answers!$C$19/100*V7 -> 0 | W8: =R8+Answers!$C$20/100*W7 -> 189.8192 | X8: =IF('Level 1'!$C$11="",0,'Level 1'!$C$11)*E8 -> 0 | Y8: =-IF('Level 2'!$C$11="",0,'Level 2'!$C$11)*F8 -> 0 | Z8: =IF('Level 3'!$C$11="",0,'Level 3'!$C$11)*G8 -> 0 | AA8: =IF('Level 4'!$C$11="",0,'Level 4'!$C$11)*(1-'Level 4'!$C$12/100)*I8 -> 0 | AB8: =IF('Level 5'!$C$11="",0,'Level 5'!$C$11)*J8 -> 0 | AC8: =IF('Level 5'!$C$12="",0,'Level 5'!$C$12)*K8 -> 0 | AD8: =IF('Level 5'!$C$13="",0,'Level 5'!$C$13)*(1-Answers!$C$14/100)*M8 -> 0 | AE8: =IF('Level 6'!$C$11="",0,'Level 6'!$C$11)*(1-Answers!$C$16/100)*S8 -> 0 | AF8: =IF('Level 6'!$C$12="",0,'Level 6'!$C$12)*(1-Answers!$C$17/100)*T8 -> 0 | AG8: =IF('Level 6'!$C$13="",0,'Level 6'!$C$13)*(1-Answers!$C$18/100)*U8 -> 0 | AH8: =IF('Level 6'!$C$14="",0,'Level 6'!$C$14)*(1-Answers!$C$19/100)*V8 -> 0 | AI8: =IF('Level 6'!$C$15="",0,'Level 6'!$C$15)*(1-Answers!$C$20/100)*W8 -> 0 | AJ8: =X8 -> 0 | AK8: =X8+Y8 -> 0 | AL8: =AK8+Z8 -> 0 | AM8: =AL8+AA8 -> 0 | AN8: =AM8+AB8+AC8+AD8 -> 0 | AO8: =AL8+AE8+AF8+AG8+AH8+AI8+AB8+AC8+AD8 -> 0 | AP8: =IF(Answers!$C$22="Yes",AO8,AN8) -> 0 | AQ8: 538.4 | AR8: 9.2 | AS8: 5539.2 | AT8: 842.7 | AU8: 601.5 | AV8: 1172.7 | AW8: 71.6 | AX8: 0 | AY8: 0 | AZ8: 261.6 | BA8: 0 | BB8: 581.1 | BC8: =AQ8+AR8+AS8+AT8+AU8+AV8+AW8 -> 8775.3 | BD8: =AQ8 -> 538.4 | BE8: =AQ8+AR8 -> 547.6 | BF8: =BE8+AS8 -> 6086.8 | BG8: =BF8+AT8 -> 6929.5 | BH8: =BG8+AU8+AV8+AW8 -> 8775.3 | BI8: =BC8 -> 8775.3 | BJ8: =IF('Level 1'!$C$31="Yes",BD8,AJ8) -> 0 | BK8: =IF('Level 2'!$C$31="Yes",BE8,AK8) -> 0 | BL8: =IF('Level 3'!$C$31="Yes",BF8,AL8) -> 0 | BM8: =IF('Level 4'!$C$31="Yes",BG8,AM8) -> 0 | BN8: =IF('Level 5'!$C$31="Yes",BH8,AN8) -> 0 | BO8: =IF('Level 6'!$C$31="Yes",BI8,AO8) -> 0 | BP8: =IF('Level 7'!$C$31="Yes",BC8,AP8) -> 0 | BQ8: =D8-AP8 -> 11484 | BR8: =BQ8^2 -> 131882256 | BS8: =(BQ8-BQ7)^2 -> 5103081 | BT8: =IF(D8>2000,ABS(BQ8)/D8,"") -> 1 | BU8: 273 | BV8: 0.5182 | BW8: 774.9 | BX8: =AA8 -> 0 | BY8: =H8 -> 141.44 | BZ8: =Z8 -> 0 | CA8: =AB8+AC8+AD8 -> 0 | CB8: =AE8+AF8+AG8+AH8+AI8 -> 0
A9: 44955 | B9: =YEAR(A9) -> 2023 | C9: =MONTH(A9) -> 1 | D9: 18475 | E9: 0.6039 | F9: 0.0454 | G9: 1.9628 | H9: 131.97 | I9: =H9+'Level 4'!$C$12/100*I8 -> 131.97 | J9: 131.51 | K9: 235.11 | L9: 76.89 | M9: =L9+Answers!$C$14/100*M8 -> 169.9188 | N9: 0 | O9: 0 | P9: 36.57 | Q9: 0 | R9: 76.92 | S9: =N9+Answers!$C$16/100*S8 -> 0 | T9: =O9+Answers!$C$17/100*T8 -> 0 | U9: =P9+Answers!$C$18/100*U8 -> 111.4292 | V9: =Q9+Answers!$C$19/100*V8 -> 0 | W9: =R9+Answers!$C$20/100*W8 -> 228.77536 | X9: =IF('Level 1'!$C$11="",0,'Level 1'!$C$11)*E9 -> 0 | Y9: =-IF('Level 2'!$C$11="",0,'Level 2'!$C$11)*F9 -> 0 | Z9: =IF('Level 3'!$C$11="",0,'Level 3'!$C$11)*G9 -> 0 | AA9: =IF('Level 4'!$C$11="",0,'Level 4'!$C$11)*(1-'Level 4'!$C$12/100)*I9 -> 0 | AB9: =IF('Level 5'!$C$11="",0,'Level 5'!$C$11)*J9 -> 0 | AC9: =IF('Level 5'!$C$12="",0,'Level 5'!$C$12)*K9 -> 0 | AD9: =IF('Level 5'!$C$13="",0,'Level 5'!$C$13)*(1-Answers!$C$14/100)*M9 -> 0 | AE9: =IF('Level 6'!$C$11="",0,'Level 6'!$C$11)*(1-Answers!$C$16/100)*S9 -> 0 | AF9: =IF('Level 6'!$C$12="",0,'Level 6'!$C$12)*(1-Answers!$C$17/100)*T9 -> 0 | AG9: =IF('Level 6'!$C$13="",0,'Level 6'!$C$13)*(1-Answers!$C$18/100)*U9 -> 0 | AH9: =IF('Level 6'!$C$14="",0,'Level 6'!$C$14)*(1-Answers!$C$19/100)*V9 -> 0 | AI9: =IF('Level 6'!$C$15="",0,'Level 6'!$C$15)*(1-Answers!$C$20/100)*W9 -> 0 | AJ9: =X9 -> 0 | AK9: =X9+Y9 -> 0 | AL9: =AK9+Z9 -> 0 | AM9: =AL9+AA9 -> 0 | AN9: =AM9+AB9+AC9+AD9 -> 0 | AO9: =AL9+AE9+AF9+AG9+AH9+AI9+AB9+AC9+AD9 -> 0 | AP9: =IF(Answers!$C$22="Yes",AO9,AN9) -> 0 | AQ9: 528.8 | AR9: -43.3 | AS9: 14912.1 | AT9: 1029.9 | AU9: 482.6 | AV9: 867.7 | AW9: 46.5 | AX9: 0 | AY9: 0 | AZ9: 318.3 | BA9: 0 | BB9: 711.6 | BC9: =AQ9+AR9+AS9+AT9+AU9+AV9+AW9 -> 17824.3 | BD9: =AQ9 -> 528.8 | BE9: =AQ9+AR9 -> 485.5 | BF9: =BE9+AS9 -> 15397.6 | BG9: =BF9+AT9 -> 16427.5 | BH9: =BG9+AU9+AV9+AW9 -> 17824.3 | BI9: =BC9 -> 17824.3 | BJ9: =IF('Level 1'!$C$31="Yes",BD9,AJ9) -> 0 | BK9: =IF('Level 2'!$C$31="Yes",BE9,AK9) -> 0 | BL9: =IF('Level 3'!$C$31="Yes",BF9,AL9) -> 0 | BM9: =IF('Level 4'!$C$31="Yes",BG9,AM9) -> 0 | BN9: =IF('Level 5'!$C$31="Yes",BH9,AN9) -> 0 | BO9: =IF('Level 6'!$C$31="Yes",BI9,AO9) -> 0 | BP9: =IF('Level 7'!$C$31="Yes",BC9,AP9) -> 0 | BQ9: =D9-AP9 -> 18475 | BR9: =BQ9^2 -> 341325625 | BS9: =(BQ9-BQ8)^2 -> 48874081 | BT9: =IF(D9>2000,ABS(BQ9)/D9,"") -> 1 | BU9: 308 | BV9: 0.4921 | BW9: 640.5 | BX9: =AA9 -> 0 | BY9: =H9 -> 131.97 | BZ9: =Z9 -> 0 | CA9: =AB9+AC9+AD9 -> 0 | CB9: =AE9+AF9+AG9+AH9+AI9 -> 0
