Workbook

Sheet Race for Life
B2: ="Chapter "&INDEX(Steps!$B$2:$B$23,State!$B$1)&" · "&INDEX(Steps!$C$2:$C$23,State!$B$1) | T2: =REPT("★",State!$B$28)&REPT("☆",10-State!$B$28)
B5: =INDEX(Steps!$D$2:$D$23,State!$B$1)
B7: =INDEX(Steps!$E$2:$E$23,State!$B$1)
B9: ="Real sign-ups (pink) and your model (blue), "&IF(State!$B$44=1,"with adverts spend as grey bars","week by week")
T10: =IF(State!$B$33="dial","Your number",IF(State!$B$33="quiz","Tap one",IF(State!$B$33="dials5","Sign-ups per £1,000",IF(State!$B$33="tests","Four tests","")))) | X10: =IF(State!$B$33="tests","Yours","") | Y10: =IF(State!$B$33="tests","Wave 1","")
T11: =IF(State!$B$33="dial",TEXT(State!$B$37,State!$B$45),IF(State!$B$33="quiz","A. "&INDEX(Steps!$O$2:$O$23,State!$B$1),IF(State!$B$33="dials5","TV: "&TEXT(State!$B$8,"0.0")&" per £1,000",IF(State!$B$33="tests","Pattern explained","")))) | U11: =IF(State!$B$33="dials5","−","") | V11: =IF(State!$B$33="dials5","+","") | W11: =IF(State!$B$33="dials5",IF(State!$B$8<Answers!$E$16*(1-Answers!$C$13),"↑",IF(State!$B$8>Answers!$E$16*(1+Answers!$C$13),"↓","✓")),"") | X11: =IF(State!$B$33="tests",TEXT(State!$B$75,"0%"),"") | Y11: =IF(State!$B$33="tests",IF(ISNUMBER(State!$C$75),TEXT(State!$C$75,"0%"),"–"),"") | Z11: =IF(State!$B$33="tests",IF(State!$B$70=1,"●","●"),"")
T12: =IF(State!$B$33="dials5","Online video: "&TEXT(State!$B$9,"0.0")&" per £1,000",IF(State!$B$33="tests","Typical weekly miss","")) | U12: =IF(State!$B$33="dials5","−","") | V12: =IF(State!$B$33="dials5","+","") | W12: =IF(State!$B$33="dials5",IF(State!$B$9<Answers!$E$17*(1-Answers!$C$13),"↑",IF(State!$B$9>Answers!$E$17*(1+Answers!$C$13),"↓","✓")),"") | X12: =IF(State!$B$33="tests",TEXT(State!$B$76,"0%"),"") | Y12: =IF(State!$B$33="tests",IF(ISNUMBER(State!$C$76),TEXT(State!$C$76,"0%"),"–"),"") | Z12: =IF(State!$B$33="tests",IF(State!$B$71=1,"●","●"),"")
T13: =IF(State!$B$33="quiz","B. "&INDEX(Steps!$P$2:$P$23,State!$B$1),IF(State!$B$33="dials5","Radio: "&TEXT(State!$B$10,"0.0")&" per £1,000",IF(State!$B$33="tests","Predicts 2025",""))) | U13: =IF(State!$B$33="dials5","−","") | V13: =IF(State!$B$33="dials5","+","") | W13: =IF(State!$B$33="dials5",IF(State!$B$10<Answers!$E$18*(1-Answers!$C$13),"↑",IF(State!$B$10>Answers!$E$18*(1+Answers!$C$13),"↓","✓")),"") | X13: =IF(State!$B$33="tests",TEXT(State!$B$77,"0%"),"") | Y13: =IF(State!$B$33="tests",IF(ISNUMBER(State!$C$77),TEXT(State!$C$77,"0%"),"–"),"") | Z13: =IF(State!$B$33="tests",IF(State!$B$72=1,"●","●"),"")
T14: =IF(State!$B$33="dials5","Posters: "&TEXT(State!$B$11,"0.0")&" per £1,000",IF(State!$B$33="tests","Unexplained 2025 change","")) | U14: =IF(State!$B$33="dials5","−","") | V14: =IF(State!$B$33="dials5","+","") | W14: =IF(State!$B$33="dials5",IF(State!$B$11<Answers!$E$19*(1-Answers!$C$13),"↑",IF(State!$B$11>Answers!$E$19*(1+Answers!$C$13),"↓","✓")),"") | X14: =IF(State!$B$33="tests",TEXT(State!$B$78,"0.0%"),"") | Y14: =IF(State!$B$33="tests",IF(ISNUMBER(State!$C$78),TEXT(State!$C$78,"0.0%"),"–"),"") | Z14: =IF(State!$B$33="tests",IF(State!$B$73=1,"●","●"),"")
T15: =IF(State!$B$33="quiz","C. "&INDEX(Steps!$Q$2:$Q$23,State!$B$1),IF(State!$B$33="dials5","Digital and social: "&TEXT(State!$B$12,"0.0")&" per £1,000","")) | U15: =IF(State!$B$33="dials5","−","") | V15: =IF(State!$B$33="dials5","+","") | W15: =IF(State!$B$33="dials5",IF(State!$B$12<Answers!$E$20*(1-Answers!$C$13),"↑",IF(State!$B$12>Answers!$E$20*(1+Answers!$C$13),"↓","✓")),"")
T16: =IF(State!$B$33="dial",INDEX(Steps!$V$2:$V$23,State!$B$1),"") | U16: =IF(State!$B$33="dial","−−","") | V16: =IF(State!$B$33="dial","−","") | X16: =IF(State!$B$33="dial","+","") | Y16: =IF(State!$B$33="dial","++","")
T18: =IF(State!$B$33="dial",IF(State!$B$37=0,"Tap + to start."&IF(State!$B$15=1," "&INDEX(Steps!$M$2:$M$23,State!$B$1),""),IF(State!$B$41=0,"↑ Higher."&IF(State!$B$15=1," "&INDEX(Steps!$M$2:$M$23,State!$B$1),""),IF(State!$B$41=2,"↓ Lower."&IF(State!$B$15=1," "&INDEX(Steps!$M$2:$M$23,State!$B$1),""),"✓ "&INDEX(Steps!$L$2:$L$23,State!$B$1)))),IF(State!$B$33="quiz",IF(State!$B$39=0,"Pick one.",IF(State!$B$39=State!$B$40,"✓ "&INDEX(Steps!$L$2:$L$23,State!$B$1),"✗ Not quite. "&INDEX(Steps!$M$2:$M$23,State!$B$1))),IF(State!$B$33="dials5",IF(AND(W11="✓",W12="✓",W13="✓",W14="✓",W15="✓"),"✓ "&INDEX(Steps!$L$2:$L$23,State!$B$1),IF(State!$B$15=1,INDEX(Steps!$M$2:$M$23,State!$B$1),"Tap − and + on each channel until five ticks show.")),IF(State!$B$33="tests",IF(State!$B$47=1,"✓ "&INDEX(Steps!$L$2:$L$23,State!$B$1),INDEX(Steps!$M$2:$M$23,State!$B$1)),INDEX(Steps!$L$2:$L$23,State!$B$1)))))
T23: =IF(OR(LEFT(T18,1)="✓",State!$B$33="info"),IF(INDEX(Steps!$N$2:$N$23,State!$B$1)="","","Economists call this: "&INDEX(Steps!$N$2:$N$23,State!$B$1)),"")
T25: =IF(State!$B$43>=3,"Pattern explained so far: "&TEXT(State!$B$42,"0%"),"")
T27: =IF(State!$B$14=1,IF(State!$B$33="dial","Wave 1's number: "&TEXT(State!$B$35,State!$B$45),IF(State!$B$33="dials5","Wave 1: "&TEXT(Answers!E16,"0.0")&", "&TEXT(Answers!E17,"0.0")&", "&TEXT(Answers!E18,"0.0")&", "&TEXT(Answers!E19,"0.0")&", "&TEXT(Answers!E20,"0.0"),IF(State!$B$33="quiz","Wave 1's answer: "&CHOOSE(State!$B$40,"A","B","C"),"Wave 1's model is the grey dashed line."))),"")
B29: ◀ Back | G29: =IF(State!$B$15=1,"Hide hint","Hint") | L29: =IF(State!$B$14=1,"Hide answer","Show answer") | Q29: ↺ | T29: Next ▶
B31: =IF(State!$B$33="dial","Tip: −− and ++ move in bigger steps.","") | Q31: Start again
B32: ="Chapter 8 · The next pound" | T32: =REPT("★",State!$B$28)&REPT("☆",10-State!$B$28)
B34: Where should the next pound go?
B35: The third biscuit never tastes like the first: each extra £1 on a channel earns a little less. Tap − and + to move money. Keep the total. Beat the 2025 plan.
B37: Channel | G37: 2025 £k | J37: Your £k | O37: Sign-ups | Q37: Return per £1 | T37: Extra sign-ups against the 2025 plan
B38: DRTV | G38: =State!$C$51 | J38: =IF(State!$B$64=1,State!$E$51,State!$B$51) | M38: − | N38: + | O38: =IF(J38<=0,0,(State!$D$51*State!$C$51*1000/90)/SQRT(State!$C$51)*SQRT(J38)) | Q38: =IF(J38<=0,0,O38*State!$B$48/1000/J38) | T38: =O51-SUMPRODUCT(State!$D$51:$D$63,State!$C$51:$C$63)*1000/90
B39: Online video | G39: =State!$C$52 | J39: =IF(State!$B$64=1,State!$E$52,State!$B$52) | M39: − | N39: + | O39: =IF(J39<=0,0,(State!$D$52*State!$C$52*1000/90)/SQRT(State!$C$52)*SQRT(J39)) | Q39: =IF(J39<=0,0,O39*State!$B$48/1000/J39) | T39: =IF(ABS(J51-G51)<=10,"Same total as 2025. Good.",IF(J51>G51,"Over budget by £"&TEXT(J51-G51,"#,##0")&"k. Take some back.","Under budget by £"&TEXT(G51-J51,"#,##0")&"k. Spend it."))
B40: Radio | G40: =State!$C$53 | J40: =IF(State!$B$64=1,State!$E$53,State!$B$53) | M40: − | N40: + | O40: =IF(J40<=0,0,(State!$D$53*State!$C$53*1000/90)/SQRT(State!$C$53)*SQRT(J40)) | Q40: =IF(J40<=0,0,O40*State!$B$48/1000/J40) | T40: =IF(ABS(J51-G51)>10,"Fix the total first.",IF(T38>=1000,"✓ You found "&TEXT(T38,"#,##0")&" extra sign-ups on the same money. The most this table allows is about 2,000.","Move money from the weakest channel to the strongest. Find 1,000 more."))
B41: Paid social | G41: =State!$C$54 | J41: =IF(State!$B$64=1,State!$E$54,State!$B$54) | M41: − | N41: + | O41: =IF(J41<=0,0,(State!$D$54*State!$C$54*1000/90)/SQRT(State!$C$54)*SQRT(J41)) | Q41: =IF(J41<=0,0,O41*State!$B$48/1000/J41)
B42: Regional | G42: =State!$C$55 | J42: =IF(State!$B$64=1,State!$E$55,State!$B$55) | M42: − | N42: + | O42: =IF(J42<=0,0,(State!$D$55*State!$C$55*1000/90)/SQRT(State!$C$55)*SQRT(J42)) | Q42: =IF(J42<=0,0,O42*State!$B$48/1000/J42)
B43: Posters | G43: =State!$C$56 | J43: =IF(State!$B$64=1,State!$E$56,State!$B$56) | M43: − | N43: + | O43: =IF(J43<=0,0,(State!$D$56*State!$C$56*1000/90)/SQRT(State!$C$56)*SQRT(J43)) | Q43: =IF(J43<=0,0,O43*State!$B$48/1000/J43) | T43: =IF(T38>=1000,"Economists call this: marginal return","")
B44: Digital audio | G44: =State!$C$57 | J44: =IF(State!$B$64=1,State!$E$57,State!$B$57) | M44: − | N44: + | O44: =IF(J44<=0,0,(State!$D$57*State!$C$57*1000/90)/SQRT(State!$C$57)*SQRT(J44)) | Q44: =IF(J44<=0,0,O44*State!$B$48/1000/J44)
B45: Display | G45: =State!$C$58 | J45: =IF(State!$B$64=1,State!$E$58,State!$B$58) | M45: − | N45: + | O45: =IF(J45<=0,0,(State!$D$58*State!$C$58*1000/90)/SQRT(State!$C$58)*SQRT(J45)) | Q45: =IF(J45<=0,0,O45*State!$B$48/1000/J45) | T45: The average £1 returned £1.66. The last £1 returned 82p. Should we add £1m to the same plan?
B46: Paid search | G46: =State!$C$59 | J46: =IF(State!$B$64=1,State!$E$59,State!$B$59) | M46: − | N46: + | O46: =IF(J46<=0,0,(State!$D$59*State!$C$59*1000/90)/SQRT(State!$C$59)*SQRT(J46)) | Q46: =IF(J46<=0,0,O46*State!$B$48/1000/J46)
B47: YouTube | G47: =State!$C$60 | J47: =IF(State!$B$64=1,State!$E$60,State!$B$60) | M47: − | N47: + | O47: =IF(J47<=0,0,(State!$D$60*State!$C$60*1000/90)/SQRT(State!$C$60)*SQRT(J47)) | Q47: =IF(J47<=0,0,O47*State!$B$48/1000/J47) | T47: A. Not yet: move money first
B48: Telemarketing | G48: =State!$C$61 | J48: =IF(State!$B$64=1,State!$E$61,State!$B$61) | M48: − | N48: + | O48: =IF(J48<=0,0,(State!$D$61*State!$C$61*1000/90)/SQRT(State!$C$61)*SQRT(J48)) | Q48: =IF(J48<=0,0,O48*State!$B$48/1000/J48) | T48: B. Yes, every £1 returns £1.66
B49: Direct mail | G49: =State!$C$62 | J49: =IF(State!$B$64=1,State!$E$62,State!$B$62) | M49: − | N49: + | O49: =IF(J49<=0,0,(State!$D$62*State!$C$62*1000/90)/SQRT(State!$C$62)*SQRT(J49)) | Q49: =IF(J49<=0,0,O49*State!$B$48/1000/J49) | T49: C. No, cut everything
B50: Door drops | G50: =State!$C$63 | J50: =IF(State!$B$64=1,State!$E$63,State!$B$63) | M50: − | N50: + | O50: =IF(J50<=0,0,(State!$D$63*State!$C$63*1000/90)/SQRT(State!$C$63)*SQRT(J50)) | Q50: =IF(J50<=0,0,O50*State!$B$48/1000/J50) | T50: =IF(State!$B$24=0,"Pick one.",IF(State!$B$24=State!$C$24,"✓ Moving money between channels was worth about £1.1m before adding a single pound.","✗ Not quite. The average pound looks great. The next pound does not."))
B51: Total | G51: =SUM(G38:G50) | J51: =SUM(J38:J50) | O51: =SUM(O38:O50) | Q51: =O51*State!$B$48/1000/J51
B52: Each channel's curve is set so the 2025 plan gives exactly Wave 1's return. Double a channel's spend and you get 41% more sign-ups, not double. AP's real curves differ by channel, so their plan gained 12,300 sign-ups with them and about 600 here. The direction is the lesson. | T52: =IF(LEFT(T50,1)="✓","Economists call this: Marginal return","")
B55: ◀ Back | G55: =IF(State!$B$64=1,"Back to my plan","Show AP's plan") | L55: Reset plan | T55: Next ▶

Sheet Brand
B2: ="Chapter 9 · Brand" | T2: =REPT("★",State!$B$28)&REPT("☆",10-State!$B$28)
B5: ="Some of today's sign-ups come from adverts people saw years ago"
B7: ="The pink line is brand consideration: the share of people who would consider supporting us. It moves slowly. Nearly a fifth of it was built by past adverts."
B9: All CRUK media spend each week (grey) and brand consideration (pink)
T10: 18.8%
T11: of today's consideration comes from past adverts. That stock is our brand equity.
T13: +0.4 points
T14: of consideration for every extra £1m of long-term media, against a drift of 0.25 points a year.
T16: £2.01
T17: is what £1 of Race for Life adverts returns over three years, up from £1.66 in the short term.
T19: Counting the long-term effect, what does £1 of Race for Life adverts return?
T20: A. £2.01
T21: B. £1.66
T22: C. 82p
T23: =IF(State!$B$25=0,"Pick one.",IF(State!$B$25=State!$C$25,"✓ Counting the long-term effect takes Race for Life adverts from £1.66 to £2.01 per pound.","✗ Not quite. Look at the third figure above."))
T25: =IF(LEFT(T23,1)="✓","Economists call this: Long-term multiplier","")
B29: ◀ Back | T29: Next ▶

Sheet Giving
B2: ="Chapter 10 · Committed Giving" | T2: =REPT("★",State!$B$28)&REPT("☆",10-State!$B$28)
B5: ="Committed Giving looks like 9p per £1 because the model only counts the first gift"
B7: ="The bars show why new monthly givers fell 23% in 2025. Inflation and the advertising cut each took about a quarter. One we chose, one we did not."
B9: Change in new Committed Givers, FY24/25 to FY25/26 (April to October), by cause. Source: Wave 1
T10: 73% | AC10: Cause | AD10: Change in new givers
T11: of new Committed Givers over three years came from marketing, direct and halo together. | AC11: Inflation | AD11: -904
AC12: Committed Giving adverts cut | AD12: -307
T13: 904 and 307 | AC13: Brand adverts cut | AD13: -107
T14: new givers lost to inflation and to the Committed Giving cut. The two biggest causes of the 23% fall. | AC14: Race for Life adverts cut | AD14: -102
AC15: Consideration slipped | AD15: -29
T16: 9p per £1 | AC16: Legacy adverts up | AD16: 41
T17: counts only the first gift of brand new givers. Not the years that follow, not the churn adverts prevent. | AC17: Less interest in Macmillan | AD17: 46
AC18: Health campaign halo | AD18: 91
T19: Why does Committed Giving show only 9p per £1? | AC19: Social Challenges adverts up | AD19: 337
T20: A. It counts only the first gift of new givers
T21: B. The adverts do not work
T22: C. Inflation
T23: =IF(State!$B$26=0,"Pick one.",IF(State!$B$26=State!$C$26,"✓ The short-term return is a floor. The years of giving that follow are not in the number yet.","✗ Not quite. Think about what a monthly giver is worth over years, not months."))
T25: =IF(LEFT(T23,1)="✓","Economists call this: Base driver and lifetime value","")
B29: ◀ Back | T29: Next ▶

Sheet Finish
B2: ="Finish" | T2: =REPT("★",State!$B$28)&REPT("☆",10-State!$B$28)
B5: ="You built the model. "&State!$B$28&" stars out of 10."
B7: ="Ten sentences you can now say in the room, each one true to Wave 1. Tap Start again to play with someone else."
B9: =IF(State!$B$17=State!$C$17,"★","☆") | C9: Econometrics | G9: Econometrics is a detective reading three years of weekly receipts to work out which pounds raised the sign-ups.
B11: =IF(State!$B$18=State!$C$18,"★","☆") | C11: Baseline | G11: Race for Life has a small base of a few hundred sign-ups a week. Nearly every other sign-up was caused by something we did.
B13: =IF(State!$B$19=State!$C$19,"★","☆") | C13: Pull-forward | G13: Sale weeks drove a fifth of sign-ups. The dip after each sale is real, and the model counts it.
B15: =IF(State!$B$20=State!$C$20,"★","☆") | C15: Adstock | G15: Our adverts keep raising sign-ups for weeks after they stop. Judge a campaign in week one and you miss most of what it earned.
B17: =IF(State!$B$21=State!$C$21,"★","☆") | C17: Halo | G17: Committed Giving adverts were quietly filling Race for Life too. When we cut them, Race for Life felt it.
B19: =IF(State!$B$22=State!$C$22,"★","☆") | C19: Multicollinearity | G19: The group number is firm. The channel split is softer. Quote the range when a decision is close.
B21: =IF(State!$B$23=State!$C$23,"★","☆") | C21: Model tests | G21: Wave 1 explains 94% of the weekly pattern, predicts weeks it never saw and left 1.4% of the 2025 fall unexplained.
B23: =IF(State!$B$24=State!$C$24,"★","☆") | C23: Marginal return | G23: The average pound returned £1.66 but the last pound returned 82p. Moving money is worth £1.1m before adding a single pound.
B25: =IF(State!$B$25=State!$C$25,"★","☆") | C25: Brand equity | G25: Nearly a fifth of the people who consider us do so because of adverts they saw years ago. The short-term return is the floor.
B27: =IF(State!$B$26=State!$C$26,"★","☆") | C27: Lifetime value | G27: Committed Giving shows 9p per pound because the model only counts the first gift of brand new givers.
B29: ◀ Back | T29: Start again ↺

Sheet Words
B2: Words: every term, one rung at a time
B3: The everyday picture first, then what it meant in Wave 1, then the sentence to say out loud.
B5: The word | C5: The everyday picture | D5: What it meant in Wave 1 | E5: Say this in the room
B6: Econometrics | C6: A detective with three years of weekly till receipts, working out which adverts raised the money. | D6: AP read 148 weeks of sign-ups against everything that happened each week and measured what each thing was worth. | E6: Econometrics is a detective reading three years of weekly receipts to work out which pounds raised the sign-ups.
B7: Baseline | C7: The customers who walk into a shop because it is there and open. | D7: A few hundred a week, from people who already consider us and from our emails. AP say the true base is close to zero. | E7: The base is what we would get with the adverts off. Everything above it is what we caused.
B8: Driver | C8: Anything that moves sign-ups up or down: an advert, a sale, the price, the time of year, inflation. | D8: AP tested 18 marketing drivers and six others and kept those with a reliable link. Weather, PR and outages had none. | E8: A driver is anything the model found that moves sign-ups.
B9: Negative driver | C9: A brake. A dearer ticket means fewer people buy it. | D9: Price and the shut autumn window pull sign-ups down. A 12% lower fee in 2025 added about 2,500 sign-ups. | E9: Price pulls sign-ups down, and the model measures the brake as well as the accelerator.
B10: Pull-forward | C10: A January sale. People who were going to buy in February buy in January instead, so February is quiet. | D10: Fewer sign-ups in the weeks after a discount window closed. AP added this so sales were not over-credited. | E10: Discounts bring sign-ups forward as well as adding new ones. The dip afterwards is real.
B11: Adstock | C11: A kettle. Switch it off and the water stays hot for a while. | D11: Each block has a memory. The short-term effect of Race for Life adverts lasts up to six months. | E11: Our adverts keep raising sign-ups for weeks after they stop, and the model measures how fast that fades.
B12: ROI, return per £1 | C12: Income earned per pound of adverts. £1.66 back for every £1 in. | D12: Sponsorship income only, about £90 per sign-up. Not entry fees, not Gift Aid, only new sign-ups. | E12: Every £1 of Race for Life adverts returned £1.66 of sponsorship income in 2025.
B13: Halo | C13: Rain on one field waters the next field too. | D13: Committed Giving adverts were 13% of Race for Life sign-ups in 2023 and 5% in 2025. Measured, not assumed. | E13: Committed Giving adverts were quietly filling Race for Life too. That is the halo.
B14: Multicollinearity | C14: Two people singing the same note. You hear the sound but cannot tell who is louder. | D14: Most Race for Life channels air in the same weeks. AP measure the group first, then split it. | E14: When channels air together the model is sure about the group and less sure about each channel.
B15: Confidence interval | C15: The range the true answer probably sits in. A forecast says 15 to 19 degrees, not 17. | D15: The Committed Giving halo is 2 to 4 sign-ups per £1,000. Quote the range when a decision is close. | E15: Every result is a range, and the range is the honest answer.
B16: R squared | C16: How much of the weekly up-and-down the model reproduces. 100% would be a perfect copy. | D16: Wave 1 explains 94%. AP's guide is above 85%. | E16: The model explains 94% of the weekly pattern in sign-ups.
... B23: Base driver | C23: The weather for a farmer. It moves the harvest and nobody on the farm controls it. | D23: Inflation cost Committed Giving about 900 new givers in FY25/26, as much as the advertising cut. | E23: Inflation and the advertising cut each cost about a quarter of new givers. One we chose, one we did not.

Sheet Under the bonnet
A1: Under the bonnet: every weekly number and formula the game uses. Nothing is hidden.
A2: Columns A to D and the AP columns are Analytic Partners' Wave 1 weekly figures, read from the charts in their July 2026 results deck. Everything else is a formula pointing at the game's dials. Spend is in thousands of pounds.
A5: Week starting | B5: Year | C5: Month | D5: Real sign-ups | E5: Shape: base | F5: Shape: brake | G5: Shape: sale | H5: RFL adverts £k | I5: RFL adstock | J5: Committed Giving £k | K5: Other causes adverts £k | N5: TV £k | O5: Online video £k | P5: Radio £k | Q5: Posters £k | R5: Digital and social £k | S5: TV adstock | T5: Online video adstock | U5: Radio adstock | V5: Posters adstock | W5: Digital adstock | X5: Your block: base | Y5: Your block: brake | Z5: Your block: sale | AA5: Your block: RFL adverts | AB5: Your block: halo | AE5: Your block: TV | AF5: Your block: Online video | AG5: Your block: Radio | AH5: Your block: Posters | AI5: Your block: Digital and social | AJ5: Model 1 base | AK5: Model 2 brake | AL5: Model 3 sale | AM5: Model 4 adverts | AN5: Model 5 halo | AO5: Model 6 split | AP5: Your final model | AQ5: AP block: base | AR5: AP block: brake | AS5: AP block: sale | AT5: AP block: RFL adverts | AU5: AP block: halo | AX5: AP block: TV | AY5: AP block: Online video | AZ5: AP block: Radio | BA5: AP block: Posters | BB5: AP block: Digital and social | BC5: Wave 1 model | BD5: Wave 1 model 1 | BE5: Wave 1 model 2 | BF5: Wave 1 model 3 | BG5: Wave 1 model 4 | BH5: Wave 1 model 5 | BI5: Wave 1 model 6 | BJ5: Chart: Wave 1 answer | BK5: Chart: your model | BL5: Chart: adverts spend £k | BQ5: Miss | BR5: Miss squared | BS5: Miss change squared | BT5: Weekly % miss (weeks over 2,000) | BU5: Real new Committed Givers | BV5: Brand consideration | BW5: All CRUK media £k
A6: 44934 | B6: =YEAR(A6) | C6: =MONTH(A6) | D6: 15469 | E6: 0.6228 | F6: 0.059 | G6: 0.7291 | H6: 112.9 | I6: =H6 | J6: 480.94 | K6: 663.21 | N6: 0 | O6: 0 | P6: 53.8 | Q6: 0 | R6: 43.63 | S6: =N6 | T6: =O6 | U6: =P6 | V6: =Q6 | W6: =R6 | X6: =State!$B$2*E6 | Y6: =-State!$B$3*F6 | Z6: =State!$B$4*G6 | AA6: =State!$B$5*(1-State!$B$6/100)*I6 | AB6: =State!$B$7*K6 | AE6: =State!$B$8*(1-Answers!$C$16/100)*S6 | AF6: =State!$B$9*(1-Answers!$C$17/100)*T6 | AG6: =State!$B$10*(1-Answers!$C$18/100)*U6 | AH6: =State!$B$11*(1-Answers!$C$19/100)*V6 | AI6: =State!$B$12*(1-Answers!$C$20/100)*W6 | AJ6: =X6 | AK6: =X6+Y6 | AL6: =AK6+Z6 | AM6: =AL6+AA6 | AN6: =AM6+AB6 | AO6: =AL6+AE6+AF6+AG6+AH6+AI6+AB6 | AP6: =IF(State!$B$46=1,AO6,AN6) | AQ6: 545.3 | AR6: -56.2 | AS6: 5539.2 | AT6: 279.3 | AU6: 2353.9 | AX6: 0 | AY6: 0 | AZ6: 141.1 | BA6: 0 | BB6: 138.2 | BC6: =AQ6+AR6+AS6+AT6+AU6 | BD6: =AQ6 | BE6: =AQ6+AR6 | BF6: =BE6+AS6 | BG6: =BF6+AT6 | BH6: =BG6+AU6 | BI6: =BC6 | BJ6: =IF(State!$B$14=1,CHOOSE(State!$B$43+1,D6,BD6,BE6,BF6,BG6,BH6,BI6),BK6) | BK6: =CHOOSE(State!$B$43+1,D6,AJ6,AK6,AL6,AM6,AN6,AO6) | BL6: =IF(State!$B$44=1,H6,0) | BQ6: =D6-AP6 | BR6: =BQ6^2 | BS6: 0 | BT6: =IF(D6>2000,ABS(BQ6)/D6,"") | BU6: 353 | BV6: 0.5182 | BW6: 848.3
A7: 44941 | B7: =YEAR(A7) | C7: =MONTH(A7) | D7: 13743 | E7: 0.6228 | F7: 0.0043 | G7: 0.7291 | H7: 127.61 | I7: =H7+State!$B$6/100*I6 | J7: 459.63 | K7: 619.16 | N7: 0 | O7: 0 | P7: 34.89 | Q7: 0 | R7: 78.97 | S7: =N7+Answers!$C$16/100*S6 | T7: =O7+Answers!$C$17/100*T6 | U7: =P7+Answers!$C$18/100*U6 | V7: =Q7+Answers!$C$19/100*V6 | W7: =R7+Answers!$C$20/100*W6 | X7: =State!$B$2*E7 | Y7: =-State!$B$3*F7 | Z7: =State!$B$4*G7 | AA7: =State!$B$5*(1-State!$B$6/100)*I7 | AB7: =State!$B$7*K7 | AE7: =State!$B$8*(1-Answers!$C$16/100)*S7 | AF7: =State!$B$9*(1-Answers!$C$17/100)*T7 | AG7: =State!$B$10*(1-Answers!$C$18/100)*U7 | AH7: =State!$B$11*(1-Answers!$C$19/100)*V7 | AI7: =State!$B$12*(1-Answers!$C$20/100)*W7 | AJ7: =X7 | AK7: =X7+Y7 | AL7: =AK7+Z7 | AM7: =AL7+AA7 | AN7: =AM7+AB7 | AO7: =AL7+AE7+AF7+AG7+AH7+AI7+AB7 | AP7: =IF(State!$B$46=1,AO7,AN7) | AQ7: 545.3 | AR7: -4.1 | AS7: 5539.2 | AT7: 561.4 | AU7: 2158.1 | AX7: 0 | AY7: 0 | AZ7: 211.4 | BA7: 0 | BB7: 349.9 | BC7: =AQ7+AR7+AS7+AT7+AU7 | BD7: =AQ7 | BE7: =AQ7+AR7 | BF7: =BE7+AS7 | BG7: =BF7+AT7 | BH7: =BG7+AU7 | BI7: =BC7 | BJ7: =IF(State!$B$14=1,CHOOSE(State!$B$43+1,D7,BD7,BE7,BF7,BG7,BH7,BI7),BK7) | BK7: =CHOOSE(State!$B$43+1,D7,AJ7,AK7,AL7,AM7,AN7,AO7) | BL7: =IF(State!$B$44=1,H7,0) | BQ7: =D7-AP7 | BR7: =BQ7^2 | BS7: =(BQ7-BQ6)^2 | BT7: =IF(D7>2000,ABS(BQ7)/D7,"") | BU7: 396 | BV7: 0.5182 | BW7: 841.2
A8: 44948 | B8: =YEAR(A8) | C8: =MONTH(A8) | D8: 11484 | E8: 0.6149 | F8: -0.0097 | G8: 0.7291 | H8: 141.44 | I8: =H8+State!$B$6/100*I7 | J8: 160.45 | K8: 547.86 | N8: 0 | O8: 0 | P8: 31.23 | Q8: 0 | R8: 98.72 | S8: =N8+Answers!$C$16/100*S7 | T8: =O8+Answers!$C$17/100*T7 | U8: =P8+Answers!$C$18/100*U7 | V8: =Q8+Answers!$C$19/100*V7 | W8: =R8+Answers!$C$20/100*W7 | X8: =State!$B$2*E8 | Y8: =-State!$B$3*F8 | Z8: =State!$B$4*G8 | AA8: =State!$B$5*(1-State!$B$6/100)*I8 | AB8: =State!$B$7*K8 | AE8: =State!$B$8*(1-Answers!$C$16/100)*S8 | AF8: =State!$B$9*(1-Answers!$C$17/100)*T8 | AG8: =State!$B$10*(1-Answers!$C$18/100)*U8 | AH8: =State!$B$11*(1-Answers!$C$19/100)*V8 | AI8: =State!$B$12*(1-Answers!$C$20/100)*W8 | AJ8: =X8 | AK8: =X8+Y8 | AL8: =AK8+Z8 | AM8: =AL8+AA8 | AN8: =AM8+AB8 | AO8: =AL8+AE8+AF8+AG8+AH8+AI8+AB8 | AP8: =IF(State!$B$46=1,AO8,AN8) | AQ8: 538.4 | AR8: 9.2 | AS8: 5539.2 | AT8: 842.7 | AU8: 1845.8 | AX8: 0 | AY8: 0 | AZ8: 261.6 | BA8: 0 | BB8: 581.1 | BC8: =AQ8+AR8+AS8+AT8+AU8 | BD8: =AQ8 | BE8: =AQ8+AR8 | BF8: =BE8+AS8 | BG8: =BF8+AT8 | BH8: =BG8+AU8 | BI8: =BC8 | BJ8: =IF(State!$B$14=1,CHOOSE(State!$B$43+1,D8,BD8,BE8,BF8,BG8,BH8,BI8),BK8) | BK8: =CHOOSE(State!$B$43+1,D8,AJ8,AK8,AL8,AM8,AN8,AO8) | BL8: =IF(State!$B$44=1,H8,0) | BQ8: =D8-AP8 | BR8: =BQ8^2 | BS8: =(BQ8-BQ7)^2 | BT8: =IF(D8>2000,ABS(BQ8)/D8,"") | BU8: 273 | BV8: 0.5182 | BW8: 774.9
A9: 44955 | B9: =YEAR(A9) | C9: =MONTH(A9) | D9: 18475 | E9: 0.6039 | F9: 0.0454 | G9: 1.9628 | H9: 131.97 | I9: =H9+State!$B$6/100*I8 | J9: 131.51 | K9: 443.52 | N9: 0 | O9: 0 | P9: 36.57 | Q9: 0 | R9: 76.92 | S9: =N9+Answers!$C$16/100*S8 | T9: =O9+Answers!$C$17/100*T8 | U9: =P9+Answers!$C$18/100*U8 | V9: =Q9+Answers!$C$19/100*V8 | W9: =R9+Answers!$C$20/100*W8 | X9: =State!$B$2*E9 | Y9: =-State!$B$3*F9 | Z9: =State!$B$4*G9 | AA9: =State!$B$5*(1-State!$B$6/100)*I9 | AB9: =State!$B$7*K9 | AE9: =State!$B$8*(1-Answers!$C$16/100)*S9 | AF9: =State!$B$9*(1-Answers!$C$17/100)*T9 | AG9: =State!$B$10*(1-Answers!$C$18/100)*U9 | AH9: =State!$B$11*(1-Answers!$C$19/100)*V9 | AI9: =State!$B$12*(1-Answers!$C$20/100)*W9 | AJ9: =X9 | AK9: =X9+Y9 | AL9: =AK9+Z9 | AM9: =AL9+AA9 | AN9: =AM9+AB9 | AO9: =AL9+AE9+AF9+AG9+AH9+AI9+AB9 | AP9: =IF(State!$B$46=1,AO9,AN9) | AQ9: 528.8 | AR9: -43.3 | AS9: 14912.1 | AT9: 1029.9 | AU9: 1396.8 | AX9: 0 | AY9: 0 | AZ9: 318.3 | BA9: 0 | BB9: 711.6 | BC9: =AQ9+AR9+AS9+AT9+AU9 | BD9: =AQ9 | BE9: =AQ9+AR9 | BF9: =BE9+AS9 | BG9: =BF9+AT9 | BH9: =BG9+AU9 | BI9: =BC9 | BJ9: =IF(State!$B$14=1,CHOOSE(State!$B$43+1,D9,BD9,BE9,BF9,BG9,BH9,BI9),BK9) | BK9: =CHOOSE(State!$B$43+1,D9,AJ9,AK9,AL9,AM9,AN9,AO9) | BL9: =IF(State!$B$44=1,H9,0) | BQ9: =D9-AP9 | BR9: =BQ9^2 | BS9: =(BQ9-BQ8)^2 | BT9: =IF(D9>2000,ABS(BQ9)/D9,"") | BU9: 308 | BV9: 0.4921 | BW9: 640.5
A10: 44962 | B10: =YEAR(A10) | C10: =MONTH(A10) | D10: 18825 | E10: 1.5192 | F10: 0.2578 | G10: 1.9628 | H10: 80.2 | I10: =H10+State!$B$6/100*I9 | J10: 541 | K10: 706.18 | N10: 0 | O10: 0 | P10: 29.67 | Q10: 0 | R10: 31.71 | S10: =N10+Answers!$C$16/100*S9 | T10: =O10+Answers!$C$17/100*T9 | U10: =P10+Answers!$C$18/100*U9 | V10: =Q10+Answers!$C$19/100*V9 | W10: =R10+Answers!$C$20/100*W9 | X10: =State!$B$2*E10 | Y10: =-State!$B$3*F10 | Z10: =State!$B$4*G10 | AA10: =State!$B$5*(1-State!$B$6/100)*I10 | AB10: =State!$B$7*K10 | AE10: =State!$B$8*(1-Answers!$C$16/100)*S10 | AF10: =State!$B$9*(1-Answers!$C$17/100)*T10 | AG10: =State!$B$10*(1-Answers!$C$18/100)*U10 | AH10: =State!$B$11*(1-Answers!$C$19/100)*V10 | AI10: =State!$B$12*(1-Answers!$C$20/100)*W10 | AJ10: =X10 | AK10: =X10+Y10 | AL10: =AK10+Z10 | AM10: =AL10+AA10 | AN10: =AM10+AB10 | AO10: =AL10+AE10+AF10+AG10+AH10+AI10+AB10 | AP10: =IF(State!$B$46=1,AO10,AN10) | AQ10: 1330.3 | AR10: -245.6 | AS10: 14912.1 | AT10: 1050 | AU10: 2428.9 | AX10: 0 | AY10: 0 | AZ10: 348.3 | BA10: 0 | BB10: 701.7 | BC10: =AQ10+AR10+AS10+AT10+AU10 | BD10: =AQ10 | BE10: =AQ10+AR10 | BF10: =BE10+AS10 | BG10: =BF10+AT10 | BH10: =BG10+AU10 | BI10: =BC10 | BJ10: =IF(State!$B$14=1,CHOOSE(State!$B$43+1,D10,BD10,BE10,BF10,BG10,BH10,BI10),BK10) | BK10: =CHOOSE(State!$B$43+1,D10,AJ10,AK10,AL10,AM10,AN10,AO10) | BL10: =IF(State!$B$44=1,H10,0) | BQ10: =D10-AP10 | BR10: =BQ10^2 | BS10: =(BQ10-BQ9)^2 | BT10: =IF(D10>2000,ABS(BQ10)/D10,"") | BU10: 500 | BV10: 0.4817 | BW10: 833
A11: 44969 | B11: =YEAR(A11) | C11: =MONTH(A11) | D11: 2994 | E11: 0.7353 | F11: 1.6658 | G11: 0 | H11: 54.91 | I11: =H11+State!$B$6/100*I10 | J11: 182.23 | K11: 537.59 | N11: 0 | O11: 0 | P11: 32.31 | Q11: 0 | R11: 19.61 | S11: =N11+Answers!$C$16/100*S10 | T11: =O11+Answers!$C$17/100*T10 | U11: =P11+Answers!$C$18/100*U10 | V11: =Q11+Answers!$C$19/100*V10 | W11: =R11+Answers!$C$20/100*W10 | X11: =State!$B$2*E11 | Y11: =-State!$B$3*F11 | Z11: =State!$B$4*G11 | AA11: =State!$B$5*(1-State!$B$6/100)*I11 | AB11: =State!$B$7*K11 | AE11: =State!$B$8*(1-Answers!$C$16/100)*S11 | AF11: =State!$B$9*(1-Answers!$C$17/100)*T11 | AG11: =State!$B$10*(1-Answers!$C$18/100)*U11 | AH11: =State!$B$11*(1-Answers!$C$19/100)*V11 | AI11: =State!$B$12*(1-Answers!$C$20/100)*W11 | AJ11: =X11 | AK11: =X11+Y11 | AL11: =AK11+Z11 | AM11: =AL11+AA11 | AN11: =AM11+AB11 | AO11: =AL11+AE11+AF11+AG11+AH11+AI11+AB11 | AP11: =IF(State!$B$46=1,AO11,AN11) | AQ11: 643.8 | AR11: -1586.5 | AS11: 0 | AT11: 1042.9 | AU11: 1749.8 | AX11: 0 | AY11: 0 | AZ11: 380.8 | BA11: 0 | BB11: 662.1 | BC11: =AQ11+AR11+AS11+AT11+AU11 | BD11: =AQ11 | BE11: =AQ11+AR11 | BF11: =BE11+AS11 | BG11: =BF11+AT11 | BH11: =BG11+AU11 | BI11: =BC11 | BJ11: =IF(State!$B$14=1,CHOOSE(State!$B$43+1,D11,BD11,BE11,BF11,BG11,BH11,BI11),BK11) | BK11: =CHOOSE(State!$B$43+1,D11,AJ11,AK11,AL11,AM11,AN11,AO11) | BL11: =IF(State!$B$44=1,H11,0) | BQ11: =D11-AP11 | BR11: =BQ11^2 | BS11: =(BQ11-BQ10)^2 | BT11: =IF(D11>2000,ABS(BQ11)/D11,"") | BU11: 462 | BV11: 0.4817 | BW11: 655.7
A12: 44976 | B12: =YEAR(A12) | C12: =MONTH(A12) | D12: 2443 | E12: 1.0168 | F12: 1.6344 | G12: 0 | H12: 53.59 | I12: =H12+State!$B$6/100*I11 | J12: 109.35 | K12: 243.78 | N12: 0 | O12: 0 | P12: 32.09 | Q12: 0 | R12: 19.06 | S12: =N12+Answers!$C$16/100*S11 | T12: =O12+Answers!$C$17/100*T11 | U12: =P12+Answers!$C$18/100*U11 | V12: =Q12+Answers!$C$19/100*V11 | W12: =R12+Answers!$C$20/100*W11 | X12: =State!$B$2*E12 | Y12: =-State!$B$3*F12 | Z12: =State!$B$4*G12 | AA12: =State!$B$5*(1-State!$B$6/100)*I12 | AB12: =State!$B$7*K12 | AE12: =State!$B$8*(1-Answers!$C$16/100)*S12 | AF12: =State!$B$9*(1-Answers!$C$17/100)*T12 | AG12: =State!$B$10*(1-Answers!$C$18/100)*U12 | AH12: =State!$B$11*(1-Answers!$C$19/100)*V12 | AI12: =State!$B$12*(1-Answers!$C$20/100)*W12 | AJ12: =X12 | AK12: =X12+Y12 | AL12: =AK12+Z12 | AM12: =AL12+AA12 | AN12: =AM12+AB12 | AO12: =AL12+AE12+AF12+AG12+AH12+AI12+AB12 | AP12: =IF(State!$B$46=1,AO12,AN12) | AQ12: 890.3 | AR12: -1556.6 | AS12: 0 | AT12: 1033.7 | AU12: 714.6 | AX12: 0 | AY12: 0 | AZ12: 407.8 | BA12: 0 | BB12: 625.9 | BC12: =AQ12+AR12+AS12+AT12+AU12 | BD12: =AQ12 | BE12: =AQ12+AR12 | BF12: =BE12+AS12 | BG12: =BF12+AT12 | BH12: =BG12+AU12 | BI12: =BC12 | BJ12: =IF(State!$B$14=1,CHOOSE(State!$B$43+1,D12,BD12,BE12,BF12,BG12,BH12,BI12),BK12) | BK12: =CHOOSE(State!$B$43+1,D12,AJ12,AK12,AL12,AM12,AN12,AO12) | BL12: =IF(State!$B$44=1,H12,0) | BQ12: =D12-AP12 | BR12: =BQ12^2 | BS12: =(BQ12-BQ11)^2 | BT12: =IF(D12>2000,ABS(BQ12)/D12,"") | BU12: 406 | BV12: 0.4817 | BW12: 396.9
A13: 44983 | B13: =YEAR(A13) | C13: =MONTH(A13) | D13: 2875 | E13: 0.656 | F13: 1.6134 | G13: 0 | H13: 54.36 | I13: =H13+State!$B$6/100*I12 | J13: 98.99 | K13: 424.79 | N13: 0 | O13: 0 | P13: 31.71 | Q13: 0 | R13: 19.77 | S13: =N13+Answers!$C$16/100*S12 | T13: =O13+Answers!$C$17/100*T12 | U13: =P13+Answers!$C$18/100*U12 | V13: =Q13+Answers!$C$19/100*V12 | W13: =R13+Answers!$C$20/100*W12 | X13: =State!$B$2*E13 | Y13: =-State!$B$3*F13 | Z13: =State!$B$4*G13 | AA13: =State!$B$5*(1-State!$B$6/100)*I13 | AB13: =State!$B$7*K13 | AE13: =State!$B$8*(1-Answers!$C$16/100)*S13 | AF13: =State!$B$9*(1-Answers!$C$17/100)*T13 | AG13: =State!$B$10*(1-Answers!$C$18/100)*U13 | AH13: =State!$B$11*(1-Answers!$C$19/100)*V13 | AI13: =State!$B$12*(1-Answers!$C$20/100)*W13 | AJ13: =X13 | AK13: =X13+Y13 | AL13: =AK13+Z13 | AM13: =AL13+AA13 | AN13: =AM13+AB13 | AO13: =AL13+AE13+AF13+AG13+AH13+AI13+AB13 | AP13: =IF(State!$B$46=1,AO13,AN13) | AQ13: 574.4 | AR13: -1536.6 | AS13: 0 | AT13: 1022 | AU13: 1375.5 | AX13: 0 | AY13: 0 | AZ13: 429.8 | BA13: 0 | BB13: 592.2 | BC13: =AQ13+AR13+AS13+AT13+AU13 | BD13: =AQ13 | BE13: =AQ13+AR13 | BF13: =BE13+AS13 | BG13: =BF13+AT13 | BH13: =BG13+AU13 | BI13: =BC13 | BJ13: =IF(State!$B$14=1,CHOOSE(State!$B$43+1,D13,BD13,BE13,BF13,BG13,BH13,BI13),BK13) | BK13: =CHOOSE(State!$B$43+1,D13,AJ13,AK13,AL13,AM13,AN13,AO13) | BL13: =IF(State!$B$44=1,H13,0) | BQ13: =D13-AP13 | BR13: =BQ13^2 | BS13: =(BQ13-BQ12)^2 | BT13: =IF(D13>2000,ABS(BQ13)/D13,"") | BU13: 344 | BV13: 0.4868 | BW13: 598.8
A14: 44990 | B14: =YEAR(A14) | C14: =MONTH(A14) | D14: 4349 | E14: 0.6973 | F14: 1.7935 | G14: 0 | H14: 42.52 | I14: =H14+State!$B$6/100*I13 | J14: 102.46 | K14: 172.1 | N14: 0 | O14: 0 | P14: 3.75 | Q14: 0 | R14: 34.42 | S14: =N14+Answers!$C$16/100*S13 | T14: =O14+Answers!$C$17/100*T13 | U14: =P14+Answers!$C$18/100*U13 | V14: =Q14+Answers!$C$19/100*V13 | W14: =R14+Answers!$C$20/100*W13 | X14: =State!$B$2*E14 | Y14: =-State!$B$3*F14 | Z14: =State!$B$4*G14 | AA14: =State!$B$5*(1-State!$B$6/100)*I14 | AB14: =State!$B$7*K14 | AE14: =State!$B$8*(1-Answers!$C$16/100)*S14 | AF14: =State!$B$9*(1-Answers!$C$17/100)*T14 | AG14: =State!$B$10*(1-Answers!$C$18/100)*U14 | AH14: =State!$B$11*(1-Answers!$C$19/100)*V14 | AI14: =State!$B$12*(1-Answers!$C$20/100)*W14 | AJ14: =X14 | AK14: =X14+Y14 | AL14: =AK14+Z14 | AM14: =AL14+AA14 | AN14: =AM14+AB14 | AO14: =AL14+AE14+AF14+AG14+AH14+AI14+AB14 | AP14: =IF(State!$B$46=1,AO14,AN14) | AQ14: 610.6 | AR14: -1708.2 | AS14: 0 | AT14: 976.8 | AU14: 594.5 | AX14: 0 | AY14: 0 | AZ14: 375.2 | BA14: 0 | BB14: 601.6 | BC14: =AQ14+AR14+AS14+AT14+AU14 | BD14: =AQ14 | BE14: =AQ14+AR14 | BF14: =BE14+AS14 | BG14: =BF14+AT14 | BH14: =BG14+AU14 | BI14: =BC14 | BJ14: =IF(State!$B$14=1,CHOOSE(State!$B$43+1,D14,BD14,BE14,BF14,BG14,BH14,BI14),BK14) | BK14: =CHOOSE(State!$B$43+1,D14,AJ14,AK14,AL14,AM14,AN14,AO14) | BL14: =IF(State!$B$44=1,H14,0) | BQ14: =D14-AP14 | BR14: =BQ14^2 | BS14: =(BQ14-BQ13)^2 | BT14: =IF(D14>2000,ABS(BQ14)/D14,"") | BU14: 249 | BV14: 0.4889 | BW14: 308.4
A15: 44997 | B15: =YEAR(A15) | C15: =MONTH(A15) | D15: 4234 | E15: 0.6036 | F15: 1.6714 | G15: 0 | H15: 118.1 | I15: =H15+State!$B$6/100*I14 | J15: 110.19 | K15: 204.7 | N15: 0 | O15: 0 | P15: 56.51 | Q15: 0 | R15: 57.35 | S15: =N15+Answers!$C$16/100*S14 | T15: =O15+Answers!$C$17/100*T14 | U15: =P15+Answers!$C$18/100*U14 | V15: =Q15+Answers!$C$19/100*V14 | W15: =R15+Answers!$C$20/100*W14 | X15: =State!$B$2*E15 | Y15: =-State!$B$3*F15 | Z15: =State!$B$4*G15 | AA15: =State!$B$5*(1-State!$B$6/100)*I15 | AB15: =State!$B$7*K15 | AE15: =State!$B$8*(1-Answers!$C$16/100)*S15 | AF15: =State!$B$9*(1-Answers!$C$17/100)*T15 | AG15: =State!$B$10*(1-Answers!$C$18/100)*U15 | AH15: =State!$B$11*(1-Answers!$C$19/100)*V15 | AI15: =State!$B$12*(1-Answers!$C$20/100)*W15 | AJ15: =X15 | AK15: =X15+Y15 | AL15: =AK15+Z15 | AM15: =AL15+AA15 | AN15: =AM15+AB15 | AO15: =AL15+AE15+AF15+AG15+AH15+AI15+AB15 | AP15: =IF(State!$B$46=1,AO15,AN15) | AQ15: 528.5 | AR15: -1591.8 | AS15: 0 | AT15: 1140.2 | AU15: 763.4 | AX15: 0 | AY15: 0 | AZ15: 467.1 | BA15: 0 | BB15: 673.2 | BC15: =AQ15+AR15+AS15+AT15+AU15 | BD15: =AQ15 | BE15: =AQ15+AR15 | BF15: =BE15+AS15 | BG15: =BF15+AT15 | BH15: =BG15+AU15 | BI15: =BC15 | BJ15: =IF(State!$B$14=1,CHOOSE(State!$B$43+1,D15,BD15,BE15,BF15,BG15,BH15,BI15),BK15) | BK15: =CHOOSE(State!$B$43+1,D15,AJ15,AK15,AL15,AM15,AN15,AO15) | BL15: =IF(State!$B$44=1,H15,0) | BQ15: =D15-AP15 | BR15: =BQ15^2 | BS15: =(BQ15-BQ14)^2 | BT15: =IF(D15>2000,ABS(BQ15)/D15,"") | BU15: 248 | BV15: 0.4889 | BW15: 383.5
A16: 45004 | B16: =YEAR(A16) | C16: =MONTH(A16) | D16: 4847 | E16: 0.6032 | F16: 1.4405 | G16: 0 | H16: 138.36 | I16: =H16+State!$B$6/100*I15 | J16: 106.94 | K16: 294.83 | N16: 0 | O16: 0 | P16: 39.38 | Q16: 0 | R16: 94.14 | S16: =N16+Answers!$C$16/100*S15 | T16: =O16+Answers!$C$17/100*T15 | U16: =P16+Answers!$C$18/100*U15 | V16: =Q16+Answers!$C$19/100*V15 | W16: =R16+Answers!$C$20/100*W15 | X16: =State!$B$2*E16 | Y16: =-State!$B$3*F16 | Z16: =State!$B$4*G16 | AA16: =State!$B$5*(1-State!$B$6/100)*I16 | AB16: =State!$B$7*K16 | AE16: =State!$B$8*(1-Answers!$C$16/100)*S16 | AF16: =State!$B$9*(1-Answers!$C$17/100)*T16 | AG16: =State!$B$10*(1-Answers!$C$18/100)*U16 | AH16: =State!$B$11*(1-Answers!$C$19/100)*V16 | AI16: =State!$B$12*(1-Answers!$C$20/100)*W16 | AJ16: =X16 | AK16: =X16+Y16 | AL16: =AK16+Z16 | AM16: =AL16+AA16 | AN16: =AM16+AB16 | AO16: =AL16+AE16+AF16+AG16+AH16+AI16+AB16 | AP16: =IF(State!$B$46=1,AO16,AN16) | AQ16: 528.2 | AR16: -1372 | AS16: 0 | AT16: 1329.2 | AU16: 1101.5 | AX16: 0 | AY16: 0 | AZ16: 500.3 | BA16: 0 | BB16: 828.9 | BC16: =AQ16+AR16+AS16+AT16+AU16 | BD16: =AQ16 | BE16: =AQ16+AR16 | BF16: =BE16+AS16 | BG16: =BF16+AT16 | BH16: =BG16+AU16 | BI16: =BC16 | BJ16: =IF(State!$B$14=1,CHOOSE(State!$B$43+1,D16,BD16,BE16,BF16,BG16,BH16,BI16),BK16) | BK16: =CHOOSE(State!$B$43+1,D16,AJ16,AK16,AL16,AM16,AN16,AO16) | BL16: =IF(State!$B$44=1,H16,0) | BQ16: =D16-AP16 | BR16: =BQ16^2 | BS16: =(BQ16-BQ15)^2 | BT16: =IF(D16>2000,ABS(BQ16)/D16,"") | BU16: 209 | BV16: 0.4889 | BW16: 493.8
A17: 45011 | B17: =YEAR(A17) | C17: =MONTH(A17) | D17: 8370 | E17: 0.6306 | F17: 0.9197 | G17: 0.4166 | H17: 757.46 | I17: =H17+State!$B$6/100*I16 | J17: 78.76 | K17: 164.31 | N17: 594.47 | O17: 108.03 | P17: 0 | Q17: 0 | R17: 46.59 | S17: =N17+Answers!$C$16/100*S16 | T17: =O17+Answers!$C$17/100*T16 | U17: =P17+Answers!$C$18/100*U16 | V17: =Q17+Answers!$C$19/100*V16 | W17: =R17+Answers!$C$20/100*W16 | X17: =State!$B$2*E17 | Y17: =-State!$B$3*F17 | Z17: =State!$B$4*G17 | AA17: =State!$B$5*(1-State!$B$6/100)*I17 | AB17: =State!$B$7*K17 | AE17: =State!$B$8*(1-Answers!$C$16/100)*S17 | AF17: =State!$B$9*(1-Answers!$C$17/100)*T17 | AG17: =State!$B$10*(1-Answers!$C$18/100)*U17 | AH17: =State!$B$11*(1-Answers!$C$19/100)*V17 | AI17: =State!$B$12*(1-Answers!$C$20/100)*W17 | AJ17: =X17 | AK17: =X17+Y17 | AL17: =AK17+Z17 | AM17: =AL17+AA17 | AN17: =AM17+AB17 | AO17: =AL17+AE17+AF17+AG17+AH17+AI17+AB17 | AP17: =IF(State!$B$46=1,AO17,AN17) | AQ17: 552.2 | AR17: -875.9 | AS17: 3165.3 | AT17: 3107.8 | AU17: 619 | AX17: 1561.9 | AY17: 282.7 | AZ17: 425.2 | BA17: 0 | BB17: 837.9 | BC17: =AQ17+AR17+AS17+AT17+AU17 | BD17: =AQ17 | BE17: =AQ17+AR17 | BF17: =BE17+AS17 | BG17: =BF17+AT17 | BH17: =BG17+AU17 | BI17: =BC17 | BJ17: =IF(State!$B$14=1,CHOOSE(State!$B$43+1,D17,BD17,BE17,BF17,BG17,BH17,BI17),BK17) | BK17: =CHOOSE(State!$B$43+1,D17,AJ17,AK17,AL17,AM17,AN17,AO17) | BL17: =IF(State!$B$44=1,H17,0) | BQ17: =D17-AP17 | BR17: =BQ17^2 | BS17: =(BQ17-BQ16)^2 | BT17: =IF(D17>2000,ABS(BQ17)/D17,"") | BU17: 237 | BV17: 0.498 | BW17: 1020.4
A18: 45018 | B18: =YEAR(A18) | C18: =MONTH(A18) | D18: 12608 | E18: 0.6303 | F18: 0.7204 | G18: 0.7291 | H18: 899.77 | I18: =H18+State!$B$6/100*I17 | J18: 82.76 | K18: 190.52 | N18: 517.88 | O18: 121.3 | P18: 48.66 | Q18: 71.54 | R18: 127.78 | S18: =N18+Answers!$C$16/100*S17 | T18: =O18+Answers!$C$17/100*T17 | U18: =P18+Answers!$C$18/100*U17 | V18: =Q18+Answers!$C$19/100*V17 | W18: =R18+Answers!$C$20/100*W17 | X18: =State!$B$2*E18 | Y18: =-State!$B$3*F18 | Z18: =State!$B$4*G18 | AA18: =State!$B$5*(1-State!$B$6/100)*I18 | AB18: =State!$B$7*K18 | AE18: =State!$B$8*(1-Answers!$C$16/100)*S18 | AF18: =State!$B$9*(1-Answers!$C$17/100)*T18 | AG18: =State!$B$10*(1-Answers!$C$18/100)*U18 | AH18: =State!$B$11*(1-Answers!$C$19/100)*V18 | AI18: =State!$B$12*(1-Answers!$C$20/100)*W18 | AJ18: =X18 | AK18: =X18+Y18 | AL18: =AK18+Z18 | AM18: =AL18+AA18 | AN18: =AM18+AB18 | AO18: =AL18+AE18+AF18+AG18+AH18+AI18+AB18 | AP18: =IF(State!$B$46=1,AO18,AN18) | AQ18: 551.9 | AR18: -686.1 | AS18: 5539.2 | AT18: 4879.1 | AU18: 707.6 | AX18: 2687.4 | AY18: 557.8 | AZ18: 489.1 | BA18: 90.4 | BB18: 1054.4 | BC18: =AQ18+AR18+AS18+AT18+AU18 | BD18: =AQ18 | BE18: =AQ18+AR18 | BF18: =BE18+AS18 | BG18: =BF18+AT18 | BH18: =BG18+AU18 | BI18: =BC18 | BJ18: =IF(State!$B$14=1,CHOOSE(State!$B$43+1,D18,BD18,BE18,BF18,BG18,BH18,BI18),BK18) | BK18: =CHOOSE(State!$B$43+1,D18,AJ18,AK18,AL18,AM18,AN18,AO18) | BL18: =IF(State!$B$44=1,H18,0) | BQ18: =D18-AP18 | BR18: =BQ18^2 | BS18: =(BQ18-BQ17)^2 | BT18: =IF(D18>2000,ABS(BQ18)/D18,"") | BU18: 221 | BV18: 0.5206 | BW18: 1138.5
... A153: 45963 | B153: =YEAR(A153) | C153: =MONTH(A153) | D153: 958 | E153: 0.5062 | F153: 1.0282 | G153: 0 | H153: 78.49 | I153: =H153+State!$B$6/100*I152 | J153: 73.14 | K153: 215.72 | N153: 40.5 | O153: 0 | P153: 0 | Q153: 0 | R153: 37.04 | S153: =N153+Answers!$C$16/100*S152 | T153: =O153+Answers!$C$17/100*T152 | U153: =P153+Answers!$C$18/100*U152 | V153: =Q153+Answers!$C$19/100*V152 | W153: =R153+Answers!$C$20/100*W152 | X153: =State!$B$2*E153 | Y153: =-State!$B$3*F153 | Z153: =State!$B$4*G153 | AA153: =State!$B$5*(1-State!$B$6/100)*I153 | AB153: =State!$B$7*K153 | AE153: =State!$B$8*(1-Answers!$C$16/100)*S153 | AF153: =State!$B$9*(1-Answers!$C$17/100)*T153 | AG153: =State!$B$10*(1-Answers!$C$18/100)*U153 | AH153: =State!$B$11*(1-Answers!$C$19/100)*V153 | AI153: =State!$B$12*(1-Answers!$C$20/100)*W153 | AJ153: =X153 | AK153: =X153+Y153 | AL153: =AK153+Z153 | AM153: =AL153+AA153 | AN153: =AM153+AB153 | AO153: =AL153+AE153+AF153+AG153+AH153+AI153+AB153 | AP153: =IF(State!$B$46=1,AO153,AN153) | AQ153: 443.3 | AR153: -979.3 | AS153: 0 | AT153: 310.1 | AU153: 520.8 | AX153: 13.1 | AY153: 22.4 | AZ153: 19.7 | BA153: 6.6 | BB153: 248.3 | BC153: =AQ153+AR153+AS153+AT153+AU153 | BD153: =AQ153 | BE153: =AQ153+AR153 | BF153: =BE153+AS153 | BG153: =BF153+AT153 | BH153: =BG153+AU153 | BI153: =BC153 | BJ153: =IF(State!$B$14=1,CHOOSE(State!$B$43+1,D153,BD153,BE153,BF153,BG153,BH153,BI153),BK153) | BK153: =CHOOSE(State!$B$43+1,D153,AJ153,AK153,AL153,AM153,AN153,AO153) | BL153: =IF(State!$B$44=1,H153,0) | BQ153: =D153-AP153 | BR153: =BQ153^2 | BS153: =(BQ153-BQ152)^2 | BT153: =IF(D153>2000,ABS(BQ153)/D153,"") | BU153: 184 | BV153: 0.5615 | BW153: 319.6

Sheet Steps
A1: step | B1: chapter | C1: chapter name | D1: title | E1: sentence | F1: type | G1: dial id | H1: small step | I1: big step | J1: answer | K1: tolerance | L1: tick | M1: hint | N1: badge | O1: option A | P1: option B | Q1: option C | R1: correct | S1: quiz index | T1: model col | U1: show bars | V1: unit | W1: format
A2: 1 | B2: 1 | C2: The receipts | D2: Three years of receipts | E2: Every week for nearly three years, this many people signed up for Race for Life. Look at the shape. | F2: info | G2: 0 | H2: 0 | I2: 0 | J2: 0 | K2: 0 | L2: The tall spikes come in spring. From August to December it goes quiet. Something causes every spike. | R2: 0 | S2: 0 | T2: 0 | U2: 0
A3: 2 | B3: 1 | C3: The receipts | D3: What made the tall spikes? | E3: Tap the answer you think is right. | F3: quiz | G3: 0 | H3: 0 | I3: 0 | J3: 0 | K3: 0 | L3: Yes. Every spike is a discount week. AP tested weather and bank holidays and found nothing. | M3: Look at the spikes. They come in the same weeks each year, whatever the weather. | N3: Driver | O3: Sale weeks | P3: Warm weather | Q3: Bank holidays | R3: 1 | S3: 1 | T3: 0 | U3: 0
A4: 3 | B4: 1 | C4: The receipts | D4: You are the detective | E4: A detective with three years of receipts works out what caused each sign-up. That is all econometrics is. You are about to do it, one block at a time. | F4: info | G4: 0 | H4: 0 | I4: 0 | J4: 0 | K4: 0 | L4: Analytic Partners did this for us in 2026 and called it Wave 1. Every number in this game is theirs. | N4: Econometrics | R4: 0 | S4: 0 | T4: 0 | U4: 0
A5: 4 | B5: 2 | C5: The shop | D5: Start with the quiet weeks | E5: In autumn almost nobody signs up. Almost. Tap + until your blue line sits on the quiet weeks. | F5: dial | G5: 1 | H5: 100 | I5: 500 | J5: =Answers!C3 | K5: =Answers!C11 | L5: About 900 a week sign up whatever we do. People who already know us, and the ones we email. | M5: Look at August to December. Hundreds, not thousands. | N5: Baseline | R5: 0 | S5: 0 | T5: 1 | U5: 0 | V5: sign-ups a week | W5: #,##0
A6: 5 | B6: 2 | C6: The shop | D6: If every advert and every sale stopped, how many would sign up a week? | E6: Tap one. | F6: quiz | G6: 0 | H6: 0 | I6: 0 | J6: 0 | K6: 0 | L6: Right. The base is small. Almost every other sign-up was caused by something we did. | M6: Look at where your blue line sat in the last step. | N6: Baseline | O6: About 900 | P6: About 9,000 | Q6: Nobody at all | R6: 1 | S6: 2 | T6: 1 | U6: 0
A7: 6 | B7: 2 | C7: The shop | D7: Now the brake | E7: A dearer ticket and a shut window push people away. Tap + until the brake feels right. Your line dips below zero in autumn. That is fine for now. | F7: dial | G7: 2 | H7: 100 | I7: 500 | J7: =Answers!C4 | K7: =Answers!C11 | L7: About 950 a week are lost to price and the shut window. Blocks can pull down as well as push up. | M7: About the same size as the base, pulling the other way. | N7: Negative driver | R7: 0 | S7: 0 | T7: 2 | U7: 0 | V7: sign-ups lost a week | W7: #,##0
A8: 7 | B8: 3 | C8: The sale | D8: Every spike is a sale | E8: Tap + until the spikes on your blue line reach the pink ones. | F8: dial | G8: 3 | H8: 500 | I8: 2000 | J8: =Answers!C5 | K8: =Answers!C11 | L8: A sale week adds about 7,600 sign-ups. Sales explained a fifth of 2025 sign-ups. | M8: How tall is a spike above the weeks around it? Thousands. | N8: Discount driver | R8: 0 | S8: 0 | T8: 3 | U8: 0 | V8: extra sign-ups in a sale week | W8: #,##0
A9: 8 | B9: 3 | C9: The sale | D9: Look at the week after a sale. What happens? | E9: Find a spike on the pink line and look one week to the right. | F9: quiz | G9: 0 | H9: 0 | I9: 0 | J9: 0 | K9: 0 | L9: Yes. Some people signed up early to get the deal. The model counts the dip so the sale is not over-credited. | M9: The week after a sale is lower than you would expect. | N9: Pull-forward | O9: A dip: some people signed up early | P9: An even bigger spike | Q9: Nothing changes | R9: 1 | S9: 3 | T9: 3 | U9: 0
A10: 9 | B10: 3 | C10: The sale | D10: Half the story | E10: ="Your model now explains "&TEXT(MAX(0,1-SUMXMY2('Under the bonnet'!$D$6:$D$153,'Under the bonnet'!$AL$6:$AL$153)/DEVSQ('Under the bonnet'!$D$6:$D$153)),"0%")&" of the weekly pattern. Sales and the shop are half the story. Adverts are the other half." | F10: info | G10: 0 | H10: 0 | I10: 0 | J10: 0 | K10: 0 | L10: A model with no adverts in it cannot say what adverts did. That is the next chapter. | N10: Pattern explained | R10: 0 | S10: 0 | T10: 3 | U10: 0
A11: 10 | B11: 4 | C11: The kettle | D11: Now the adverts | E11: The grey bars are what we spent on Race for Life adverts each week. Tap + to set how many sign-ups each £1,000 brings. | F11: dial | G11: 4 | H11: 1 | I11: 5 | J11: =Answers!C6 | K11: =Answers!C11 | L11: ="About 16 sign-ups per £1,000. That is £"&TEXT(State!$B$5*State!$B$48/1000,"0.00")&" of sponsorship for every £1 spent." | M11: Somewhere between 5 and 30. | N11: Response | R11: 0 | S11: 0 | T11: 4 | U11: 1 | V11: sign-ups per £1,000 | W11: #,##0.0
A12: 11 | B12: 4 | C12: The kettle | D12: The kettle | E12: Adverts keep working after they stop, like a kettle stays hot. Tap + on the memory until your line matches the shape of the pink one. | F12: dial | G12: 5 | H12: 10 | I12: 10 | J12: =Answers!C7 | K12: =Answers!C12 | L12: Memory of 80%: the effect fades slowly over months. Judge a campaign in week one and you miss most of it. | M12: Try a high number. Adverts fade over months, not days. | N12: Adstock | R12: 0 | S12: 0 | T12: 4 | U12: 1 | V12: % of last week's effect still here | W12: 0"%"
A13: 12 | B13: 4 | C13: The kettle | D13: Every £1 of Race for Life adverts brought back how much sponsorship in 2025? | E13: Tap one. | F13: quiz | G13: 0 | H13: 0 | I13: 0 | J13: 0 | K13: 0 | L13: Yes. £1.66 on average. Remember the word average. It matters in chapter 8. | M13: Look at the £ figure from two steps ago. | N13: ROI, return per £1 | O13: £1.66 | P13: 16p | Q13: £16 | R13: 1 | S13: 4 | T13: 4 | U13: 1
A14: 13 | B14: 5 | C14: The next field | D14: Rain on the next field | E14: Committed Giving, Legacy and Brand adverts never mention Race for Life. Yet sign-ups rose when they ran. Tap + to add their effect. | F14: dial | G14: 6 | H14: 0.5 | I14: 2 | J14: =Answers!C8 | K14: =Answers!C11 | L14: About 3 per £1,000. Small per pound, but the spend is large. It adds up to 15% of sign-ups. | M14: Small. Under 10. | N14: Halo | R14: 0 | S14: 0 | T14: 5 | U14: 0 | V14: sign-ups per £1,000 of other adverts | W14: 0.0
A15: 14 | B15: 5 | C15: The next field | D15: What the 2025 cut cost | E15: ="In 2025 we spent 42% less on Committed Giving adverts. Your model says Race for Life lost "&TEXT(State!$B$7*(SUMIFS('Under the bonnet'!$J$6:$J$153,'Under the bonnet'!$B$6:$B$153,2024,'Under the bonnet'!$C$6:$C$153,"<=10")-SUMIFS('Under the bonnet'!$J$6:$J$153,'Under the bonnet'!$B$6:$B$153,2025,'Under the bonnet'!$C$6:$C$153,"<=10")),"#,##0")&" sign-ups because of it. Wave 1 said 9,139." | F15: info | G15: 0 | H15: 0 | I15: 0 | J15: 0 | K15: 0 | L15: Two budgets, one shared result. Yours is lower than Wave 1's because you gave every other cause the same strength per pound. AP found Committed Giving the strongest of the three. | N15: Halo | R15: 0 | S15: 0 | T15: 5 | U15: 0
A16: 15 | B16: 5 | C16: The next field | D16: Adverts for one cause helping another is called? | E16: Tap one. | F16: quiz | G16: 0 | H16: 0 | I16: 0 | J16: 0 | K16: 0 | L16: A halo. Committed Giving adverts were quietly filling Race for Life too. | M16: Think of rain on the next field. | N16: Halo | O16: A halo | P16: A discount | Q16: Seasonality | R16: 1 | S16: 5 | T16: 5 | U16: 0
A17: 16 | B17: 6 | C17: Who sang louder | D17: Split the adverts into five | E17: TV, video, radio, posters, digital. They mostly run in the same weeks. Tap − and + on each until all five ticks show. | F17: dials5 | G17: 0 | H17: 1 | I17: 1 | J17: 0 | K17: =Answers!C13 | L17: All five about right. Notice how loose the checks were. That is the point. | M17: Your chapter 4 number is the guide for each. Posters are much weaker. | N17: Multicollinearity | R17: 0 | S17: 0 | T17: 6 | U17: 0
A18: 17 | B18: 6 | C18: Who sang louder | D18: The group is firm, the split is soft | E18: ="With one adverts block your pattern score was "&TEXT(MAX(0,1-SUMXMY2('Under the bonnet'!$D$6:$D$153,'Under the bonnet'!$AN$6:$AN$153)/DEVSQ('Under the bonnet'!$D$6:$D$153)),"0%")&". With five it is "&TEXT(MAX(0,1-SUMXMY2('Under the bonnet'!$D$6:$D$153,'Under the bonnet'!$AO$6:$AO$153)/DEVSQ('Under the bonnet'!$D$6:$D$153)),"0%")&". The split changes the story, not the fit." | F18: info | G18: 0 | H18: 0 | I18: 0 | J18: 0 | K18: 0 | L18: Two people singing the same note: you hear the sound but cannot tell who is louder. Quote the range on any single channel. | N18: Multicollinearity | R18: 0 | S18: 0 | T18: 6 | U18: 0
A19: 18 | B19: 6 | C19: Who sang louder | D19: Which channel was AP least sure about? | E19: Tap one. | F19: quiz | G19: 0 | H19: 0 | I19: 0 | J19: 0 | K19: 0 | L19: Posters: about 60p back per £1, with a wide range either side. | M19: Which one needed the smallest number? | N19: Confidence interval | O19: Posters | P19: TV | Q19: Digital and social | R19: 1 | S19: 6 | T19: 6 | U19: 0
A20: 19 | B20: 7 | C20: Any good? | D20: Is your model any good? | E20: Four questions judge any model. Your scores sit beside Wave 1's. | F20: tests | G20: 0 | H20: 0 | I20: 0 | J20: 0 | K20: 0 | L20: Green all round. Your model explains the pattern, predicts weeks it never saw and leaves little unexplained. | M20: Amber? Go back a chapter and adjust that block. | N20: R squared, MAPE, holdout | R20: 0 | S20: 0 | T20: 6 | U20: 0
A21: 20 | B21: 7 | C21: Any good? | D21: A model copies the past perfectly but predicts 2025 badly. What went wrong? | E21: Tap one. | F21: quiz | G21: 0 | H21: 0 | I21: 0 | J21: 0 | K21: 0 | L21: Yes. That is why AP test every model on weeks it never saw. | M21: Think of a student who memorises last year's exam paper. | N21: Holdout test | O21: It learned the noise, not the pattern | P21: It needs more adverts | Q21: 2025 was just unusual | R21: 1 | S21: 7 | T21: 6 | U21: 0
A22: 21 | B22: 7 | C22: Any good? | D22: You built the model | E22: Seven chapters, one model, every number Wave 1's. Next: where should the next pound go? | F22: info | G22: 0 | H22: 0 | I22: 0 | J22: 0 | K22: 0 | L22: Say it in the room: about half of Race for Life sign-ups come from Race for Life adverts, a fifth from sales and 15% from other causes' adverts. | N22: Decomposition | R22: 0 | S22: 0 | T22: 6 | U22: 0
A23: 22 | B23: 8 | C23: The next pound | D23: Where should the next pound go? | E23: Chapter 8 is the budget game, just below this screen. Scroll down if you cannot see it. | F23: info | G23: 0 | H23: 0 | I23: 0 | J23: 0 | K23: 0 | L23: Tap − and + to move money between the thirteen 2025 channels. Keep the total. Beat the 2025 plan, then answer the question. | R23: 0 | S23: 0 | T23: 6 | U23: 0

Sheet State
A1: Step (1 to 21) | B1: 1 | D1: No macros? This tab is the control panel. Type the step number in B1 (1 to 22; step 22 is the budget game lower down the Race for Life tab), the dials in B2 to B12, quiz answers in B17 to B26 and the budget in B51 to B63. Set B30 to 2 (Brand), 3 (Giving) or 4 (Finish) to move on.
A2: Base: sign-ups a week | B2: 0
A3: Brake: sign-ups lost a week | B3: 0
A4: Sale: extra sign-ups | B4: 0
A5: Adverts: sign-ups per £1,000 | B5: 0
A6: Memory % | B6: 0
A7: Halo: sign-ups per £1,000 | B7: 0
A8: TV per £1,000 | B8: 0
A9: Online video per £1,000 | B9: 0
A10: Radio per £1,000 | B10: 0
A11: Posters per £1,000 | B11: 0
A12: Digital and social per £1,000 | B12: 0
A14: Show answer (1 = yes) | B14: 0
A15: Show hint (1 = yes) | B15: 0
A17: Quiz 1 answer chosen (1 to 3) | B17: 0 | C17: 1
A18: Quiz 2 answer chosen (1 to 3) | B18: 0 | C18: 1
A19: Quiz 3 answer chosen (1 to 3) | B19: 0 | C19: 1
A20: Quiz 4 answer chosen (1 to 3) | B20: 0 | C20: 1
A21: Quiz 5 answer chosen (1 to 3) | B21: 0 | C21: 1
A22: Quiz 6 answer chosen (1 to 3) | B22: 0 | C22: 1
A23: Quiz 7 answer chosen (1 to 3) | B23: 0 | C23: 1
A24: Quiz 8 answer chosen (1 to 3) | B24: 0 | C24: 1
A25: Quiz 9 answer chosen (1 to 3) | B25: 0 | C25: 1
A26: Quiz 10 answer chosen (1 to 3) | B26: 0 | C26: 1
A28: Stars | B28: =SUMPRODUCT(--(B17:B26=C17:C26))
A30: Stage (1 Race for Life, 2 Brand, 3 Giving, 4 Finish) | B30: 1
A31: Progress (of 24) | B31: =IF(B30=1,MIN(22,B1),MIN(24,22+B30-1))
A33: Step type | B33: =INDEX(Steps!$F$2:$F$23,State!$B$1)
A34: Dial id | B34: =INDEX(Steps!$G$2:$G$23,State!$B$1)
A35: Answer | B35: =INDEX(Steps!$J$2:$J$23,State!$B$1)
A36: Tolerance | B36: =INDEX(Steps!$K$2:$K$23,State!$B$1)
A37: Current value | B37: =IF(B34=0,0,INDEX($B$2:$B$12,B34))
A38: Quiz index | B38: =INDEX(Steps!$S$2:$S$23,State!$B$1)
A39: Chosen | B39: =IF(B38=0,0,INDEX($B$17:$B$26,B38))
A40: Correct | B40: =INDEX(Steps!$R$2:$R$23,State!$B$1)
A41: Dial verdict (0 low, 1 ok, 2 high) | B41: =IF(B34=0,1,IF(B34=5,IF(B37<B35-B36,0,IF(B37>B35+B36,2,1)),IF(B37<B35*(1-B36),0,IF(B37>B35*(1+B36),2,1))))
A42: Pattern explained (chart model) | B42: =MAX(0,1-SUMXMY2('Under the bonnet'!$D$6:$D$153,'Under the bonnet'!$BK$6:$BK$153)/DEVSQ('Under the bonnet'!$D$6:$D$153))
A43: Model column | B43: =INDEX(Steps!$T$2:$T$23,State!$B$1)
A44: Show bars | B44: =INDEX(Steps!$U$2:$U$23,State!$B$1)
A45: Number format | B45: =INDEX(Steps!$W$2:$W$23,State!$B$1)
...

Sheet Room notes
B2: Room notes: running the game with a team in 45 minutes
B3: For the person leading. Unhide from the sheet list. The answers are here, so do not share the screen with this tab open.
B5: 0 to 5 | C5: Open the Race for Life tab on the big screen. Chapter 1, one person tapping. Ask the room what made the spikes before anyone taps.
B6: 5 to 15 | C6: Chapters 2 and 3 together. Ask for a show of hands before each number: higher or lower than a thousand? The base surprises people. Let it.
B7: 15 to 25 | C7: Chapter 4. Ask the room to guess the memory before you touch it. Most say 20%. Show what 80% does. Name adstock only after the line fits.
B8: 25 to 32 | C8: Chapter 5. Add the halo, then read the 42% step out loud and stop. Let the room say what it means for next year.
B9: 32 to 38 | C9: Chapter 6 in pairs on laptops. The point is the catch, not the numbers. Ask: which channel are you least sure of, and why?
B10: 38 to 45 | C10: Chapter 8 as a race: first to 1,000 extra sign-ups on the same money. Close on average versus last pound. The Brand and Giving tabs are homework.
B11: Answer key | C11: Base 876. Brake 952. Sale 7,598. Adverts 16.1 per £1,000, memory 80%. Halo 2.86 per £1,000. Channels: TV 17.0, Online video 17.4, Radio 17.4, Posters 6.1, Digital and social 17.6. Every quiz answer is A.
B12: If asked "is this just correlation?" | C12: Partly, and AP say so. Three things make it more: it controls for everything at once, it is tested on weeks it never saw, and channels that stopped (Race for Life TV after 2024) let it see what happens without them.
B13: If asked "the halo felt too big" | C13: It did, and AP rebuilt it. They now measure Committed Giving as one block. The halo fell and is still 5% of 2025 sign-ups and 9,139 of the 2025 decline.
B14: Budget chapter | C14: Best possible on the game's curves is about 2,000 extra: cut posters and telemarketing, add DRTV and online video. AP's own plan shows the same direction.

Sheet Answers
A1: Answer key, fitted to the Wave 1 decomposition. Hidden so the game stays a game.
B3: Base: sign-ups a week | C3: 876
B4: Brake: sign-ups lost a week | C4: 952
B5: Sale: extra sign-ups in a sale week | C5: 7600
B6: RFL adverts: sign-ups per £1,000 | C6: 16.1
B7: RFL adverts: memory % | C7: 80
B8: Halo: sign-ups per £1,000 of other adverts | C8: 2.86
B11: Tolerance on a dial | C11: 0.25
B12: Tolerance on memory (points) | C12: 10
B13: Tolerance on a channel | C13: 0.35
B16: TV: memory % | C16: 80 | D16: TV: sign-ups per £1,000 | E16: 17
B17: Online video: memory % | C17: 80 | D17: Online video: sign-ups per £1,000 | E17: 17.4
B18: Radio: memory % | C18: 80 | D18: Radio: sign-ups per £1,000 | E18: 17.4
B19: Posters: memory % | C19: 80 | D19: Posters: sign-ups per £1,000 | E19: 6.1
B20: Digital and social: memory % | C20: 80 | D20: Digital and social: sign-ups per £1,000 | E20: 17.6
